[2025-10-14 17:49:13,194] {processor.py:153} INFO - Started process (PID=28370) to work on /root/Projects/etlX/airflow/dags/x_dag.py
[2025-10-14 17:49:13,195] {processor.py:641} INFO - Processing file /root/Projects/etlX/airflow/dags/x_dag.py for tasks to queue
[2025-10-14 17:49:13,196] {logging_mixin.py:115} INFO - [2025-10-14 17:49:13,196] {dagbag.py:507} INFO - Filling up the DagBag from /root/Projects/etlX/airflow/dags/x_dag.py
[2025-10-14 17:49:13,216] {logging_mixin.py:115} INFO - [2025-10-14 17:49:13,201] {dagbag.py:320} ERROR - Failed to import: /root/Projects/etlX/airflow/dags/x_dag.py
Traceback (most recent call last):
  File "/root/Projects/etlX/venv/lib/python3.9/site-packages/airflow/models/dagbag.py", line 317, in parse
    loader.exec_module(new_module)
  File "<frozen importlib._bootstrap_external>", line 855, in exec_module
  File "<frozen importlib._bootstrap>", line 228, in _call_with_frames_removed
  File "/root/Projects/etlX/airflow/dags/x_dag.py", line 6, in <module>
    from operators.x_operator import XOperator
ModuleNotFoundError: No module named 'operators'
[2025-10-14 17:49:13,216] {processor.py:653} WARNING - No viable dags retrieved from /root/Projects/etlX/airflow/dags/x_dag.py
[2025-10-14 17:49:13,236] {processor.py:161} INFO - Processing /root/Projects/etlX/airflow/dags/x_dag.py took 0.046 seconds
[2025-10-14 17:49:44,271] {processor.py:153} INFO - Started process (PID=28535) to work on /root/Projects/etlX/airflow/dags/x_dag.py
[2025-10-14 17:49:44,271] {processor.py:641} INFO - Processing file /root/Projects/etlX/airflow/dags/x_dag.py for tasks to queue
[2025-10-14 17:49:44,272] {logging_mixin.py:115} INFO - [2025-10-14 17:49:44,272] {dagbag.py:507} INFO - Filling up the DagBag from /root/Projects/etlX/airflow/dags/x_dag.py
[2025-10-14 17:49:44,276] {logging_mixin.py:115} INFO - [2025-10-14 17:49:44,275] {dagbag.py:320} ERROR - Failed to import: /root/Projects/etlX/airflow/dags/x_dag.py
Traceback (most recent call last):
  File "/root/Projects/etlX/venv/lib/python3.9/site-packages/airflow/models/dagbag.py", line 317, in parse
    loader.exec_module(new_module)
  File "<frozen importlib._bootstrap_external>", line 855, in exec_module
  File "<frozen importlib._bootstrap>", line 228, in _call_with_frames_removed
  File "/root/Projects/etlX/airflow/dags/x_dag.py", line 6, in <module>
    from operators.x_operator import XOperator
ModuleNotFoundError: No module named 'operators'
[2025-10-14 17:49:44,277] {processor.py:653} WARNING - No viable dags retrieved from /root/Projects/etlX/airflow/dags/x_dag.py
[2025-10-14 17:49:44,297] {processor.py:161} INFO - Processing /root/Projects/etlX/airflow/dags/x_dag.py took 0.031 seconds
[2025-10-14 17:50:14,532] {processor.py:153} INFO - Started process (PID=28557) to work on /root/Projects/etlX/airflow/dags/x_dag.py
[2025-10-14 17:50:14,533] {processor.py:641} INFO - Processing file /root/Projects/etlX/airflow/dags/x_dag.py for tasks to queue
[2025-10-14 17:50:14,534] {logging_mixin.py:115} INFO - [2025-10-14 17:50:14,534] {dagbag.py:507} INFO - Filling up the DagBag from /root/Projects/etlX/airflow/dags/x_dag.py
[2025-10-14 17:50:14,539] {logging_mixin.py:115} INFO - [2025-10-14 17:50:14,538] {dagbag.py:320} ERROR - Failed to import: /root/Projects/etlX/airflow/dags/x_dag.py
Traceback (most recent call last):
  File "/root/Projects/etlX/venv/lib/python3.9/site-packages/airflow/models/dagbag.py", line 317, in parse
    loader.exec_module(new_module)
  File "<frozen importlib._bootstrap_external>", line 855, in exec_module
  File "<frozen importlib._bootstrap>", line 228, in _call_with_frames_removed
  File "/root/Projects/etlX/airflow/dags/x_dag.py", line 6, in <module>
    from operators.x_operator import XOperator
ModuleNotFoundError: No module named 'operators'
[2025-10-14 17:50:14,540] {processor.py:653} WARNING - No viable dags retrieved from /root/Projects/etlX/airflow/dags/x_dag.py
[2025-10-14 17:50:14,561] {processor.py:161} INFO - Processing /root/Projects/etlX/airflow/dags/x_dag.py took 0.037 seconds
[2025-10-14 17:50:44,758] {processor.py:153} INFO - Started process (PID=28576) to work on /root/Projects/etlX/airflow/dags/x_dag.py
[2025-10-14 17:50:44,759] {processor.py:641} INFO - Processing file /root/Projects/etlX/airflow/dags/x_dag.py for tasks to queue
[2025-10-14 17:50:44,759] {logging_mixin.py:115} INFO - [2025-10-14 17:50:44,759] {dagbag.py:507} INFO - Filling up the DagBag from /root/Projects/etlX/airflow/dags/x_dag.py
[2025-10-14 17:50:44,764] {logging_mixin.py:115} INFO - [2025-10-14 17:50:44,763] {dagbag.py:320} ERROR - Failed to import: /root/Projects/etlX/airflow/dags/x_dag.py
Traceback (most recent call last):
  File "/root/Projects/etlX/venv/lib/python3.9/site-packages/airflow/models/dagbag.py", line 317, in parse
    loader.exec_module(new_module)
  File "<frozen importlib._bootstrap_external>", line 855, in exec_module
  File "<frozen importlib._bootstrap>", line 228, in _call_with_frames_removed
  File "/root/Projects/etlX/airflow/dags/x_dag.py", line 6, in <module>
    from operators.x_operator import XOperator
ModuleNotFoundError: No module named 'operators'
[2025-10-14 17:50:44,764] {processor.py:653} WARNING - No viable dags retrieved from /root/Projects/etlX/airflow/dags/x_dag.py
[2025-10-14 17:50:44,787] {processor.py:161} INFO - Processing /root/Projects/etlX/airflow/dags/x_dag.py took 0.033 seconds
[2025-10-14 17:51:15,014] {processor.py:153} INFO - Started process (PID=28600) to work on /root/Projects/etlX/airflow/dags/x_dag.py
[2025-10-14 17:51:15,014] {processor.py:641} INFO - Processing file /root/Projects/etlX/airflow/dags/x_dag.py for tasks to queue
[2025-10-14 17:51:15,015] {logging_mixin.py:115} INFO - [2025-10-14 17:51:15,015] {dagbag.py:507} INFO - Filling up the DagBag from /root/Projects/etlX/airflow/dags/x_dag.py
[2025-10-14 17:51:15,052] {logging_mixin.py:115} INFO - [2025-10-14 17:51:15,052] {base.py:68} INFO - Using connection ID 'x_default' for task execution.
[2025-10-14 17:51:15,056] {logging_mixin.py:115} INFO - [2025-10-14 17:51:15,056] {x_hook.py:40} INFO - Requisição: https://api.twitter.com/2/tweets/search/recent?query=datascience&tweet.fields=author_id,conversation_id,created_at,id,in_reply_to_user_id,public_metrics,lang,text&expansions=author_id&user.fields=id,name,username,created_at&start_time=2025-10-13T17:51:15.00Z&end_time=2025-10-14T17:51:15.00Z
[2025-10-14 17:51:15,439] {logging_mixin.py:115} INFO - [2025-10-14 17:51:15,439] {x_hook.py:40} INFO - Requisição: https://api.twitter.com/2/tweets/search/recent?query=datascience&tweet.fields=author_id,conversation_id,created_at,id,in_reply_to_user_id,public_metrics,lang,text&expansions=author_id&user.fields=id,name,username,created_at&start_time=2025-10-13T17:51:15.00Z&end_time=2025-10-14T17:51:15.00Z&next_token=b26v89c19zqg8o3fsch8cbjl16si8sj6tfysbyotgc0vx
[2025-10-14 17:51:15,599] {logging_mixin.py:115} INFO - [2025-10-14 17:51:15,599] {http.py:142} ERROR - HTTP error: Too Many Requests
[2025-10-14 17:51:15,599] {logging_mixin.py:115} INFO - [2025-10-14 17:51:15,599] {http.py:143} ERROR - {"title":"Too Many Requests","detail":"Too Many Requests","type":"about:blank","status":429}
[2025-10-14 17:51:15,601] {logging_mixin.py:115} INFO - [2025-10-14 17:51:15,599] {dagbag.py:320} ERROR - Failed to import: /root/Projects/etlX/airflow/dags/x_dag.py
Traceback (most recent call last):
  File "/root/Projects/etlX/venv/lib/python3.9/site-packages/airflow/providers/http/hooks/http.py", line 140, in check_response
    response.raise_for_status()
  File "/root/Projects/etlX/venv/lib/python3.9/site-packages/requests/models.py", line 960, in raise_for_status
    raise HTTPError(http_error_msg, response=self)
requests.exceptions.HTTPError: 429 Client Error: Too Many Requests for url: https://api.twitter.com/2/tweets/search/recent?query=datascience&tweet.fields=author_id,conversation_id,created_at,id,in_reply_to_user_id,public_metrics,lang,text&expansions=author_id&user.fields=id,name,username,created_at&start_time=2025-10-13T17:51:15.00Z&end_time=2025-10-14T17:51:15.00Z&next_token=b26v89c19zqg8o3fsch8cbjl16si8sj6tfysbyotgc0vx

During handling of the above exception, another exception occurred:

Traceback (most recent call last):
  File "/root/Projects/etlX/venv/lib/python3.9/site-packages/airflow/models/dagbag.py", line 317, in parse
    loader.exec_module(new_module)
  File "<frozen importlib._bootstrap_external>", line 855, in exec_module
  File "<frozen importlib._bootstrap>", line 228, in _call_with_frames_removed
  File "/root/Projects/etlX/airflow/dags/x_dag.py", line 22, in <module>
    x_operator.execute(ti.task_id)
  File "/root/Projects/etlX/airflow/operators/x_operator.py", line 34, in execute
    for pg in XHook(end_time, start_time, query).run():
  File "/root/Projects/etlX/airflow/hook/x_hook.py", line 68, in run
    return self.pagination(url_raw, session)
  File "/root/Projects/etlX/airflow/hook/x_hook.py", line 57, in pagination
    response = self.conn_to_endpoint(url, session)
  File "/root/Projects/etlX/airflow/hook/x_hook.py", line 42, in conn_to_endpoint
    response = self.run_and_check(session, prep, {})
  File "/root/Projects/etlX/venv/lib/python3.9/site-packages/airflow/providers/http/hooks/http.py", line 183, in run_and_check
    self.check_response(response)
  File "/root/Projects/etlX/venv/lib/python3.9/site-packages/airflow/providers/http/hooks/http.py", line 144, in check_response
    raise AirflowException(str(response.status_code) + ":" + response.reason)
airflow.exceptions.AirflowException: 429:Too Many Requests
[2025-10-14 17:51:15,602] {processor.py:653} WARNING - No viable dags retrieved from /root/Projects/etlX/airflow/dags/x_dag.py
[2025-10-14 17:51:15,615] {processor.py:161} INFO - Processing /root/Projects/etlX/airflow/dags/x_dag.py took 0.607 seconds
[2025-10-14 17:51:46,293] {processor.py:153} INFO - Started process (PID=28624) to work on /root/Projects/etlX/airflow/dags/x_dag.py
[2025-10-14 17:51:46,294] {processor.py:641} INFO - Processing file /root/Projects/etlX/airflow/dags/x_dag.py for tasks to queue
[2025-10-14 17:51:46,297] {logging_mixin.py:115} INFO - [2025-10-14 17:51:46,297] {dagbag.py:507} INFO - Filling up the DagBag from /root/Projects/etlX/airflow/dags/x_dag.py
[2025-10-14 17:51:46,332] {logging_mixin.py:115} INFO - [2025-10-14 17:51:46,332] {base.py:68} INFO - Using connection ID 'x_default' for task execution.
[2025-10-14 17:51:46,336] {logging_mixin.py:115} INFO - [2025-10-14 17:51:46,336] {x_hook.py:40} INFO - Requisição: https://api.twitter.com/2/tweets/search/recent?query=datascience&tweet.fields=author_id,conversation_id,created_at,id,in_reply_to_user_id,public_metrics,lang,text&expansions=author_id&user.fields=id,name,username,created_at&start_time=2025-10-13T17:51:46.00Z&end_time=2025-10-14T17:51:46.00Z
[2025-10-14 17:51:46,579] {logging_mixin.py:115} INFO - [2025-10-14 17:51:46,579] {http.py:142} ERROR - HTTP error: Too Many Requests
[2025-10-14 17:51:46,579] {logging_mixin.py:115} INFO - [2025-10-14 17:51:46,579] {http.py:143} ERROR - {"title":"Too Many Requests","detail":"Too Many Requests","type":"about:blank","status":429}
[2025-10-14 17:51:46,582] {logging_mixin.py:115} INFO - [2025-10-14 17:51:46,579] {dagbag.py:320} ERROR - Failed to import: /root/Projects/etlX/airflow/dags/x_dag.py
Traceback (most recent call last):
  File "/root/Projects/etlX/venv/lib/python3.9/site-packages/airflow/providers/http/hooks/http.py", line 140, in check_response
    response.raise_for_status()
  File "/root/Projects/etlX/venv/lib/python3.9/site-packages/requests/models.py", line 960, in raise_for_status
    raise HTTPError(http_error_msg, response=self)
requests.exceptions.HTTPError: 429 Client Error: Too Many Requests for url: https://api.twitter.com/2/tweets/search/recent?query=datascience&tweet.fields=author_id,conversation_id,created_at,id,in_reply_to_user_id,public_metrics,lang,text&expansions=author_id&user.fields=id,name,username,created_at&start_time=2025-10-13T17:51:46.00Z&end_time=2025-10-14T17:51:46.00Z

During handling of the above exception, another exception occurred:

Traceback (most recent call last):
  File "/root/Projects/etlX/venv/lib/python3.9/site-packages/airflow/models/dagbag.py", line 317, in parse
    loader.exec_module(new_module)
  File "<frozen importlib._bootstrap_external>", line 855, in exec_module
  File "<frozen importlib._bootstrap>", line 228, in _call_with_frames_removed
  File "/root/Projects/etlX/airflow/dags/x_dag.py", line 22, in <module>
    x_operator.execute(ti.task_id)
  File "/root/Projects/etlX/airflow/operators/x_operator.py", line 34, in execute
    for pg in XHook(end_time, start_time, query).run():
  File "/root/Projects/etlX/airflow/hook/x_hook.py", line 68, in run
    return self.pagination(url_raw, session)
  File "/root/Projects/etlX/airflow/hook/x_hook.py", line 47, in pagination
    response = self.conn_to_endpoint(url_raw, session)
  File "/root/Projects/etlX/airflow/hook/x_hook.py", line 42, in conn_to_endpoint
    response = self.run_and_check(session, prep, {})
  File "/root/Projects/etlX/venv/lib/python3.9/site-packages/airflow/providers/http/hooks/http.py", line 183, in run_and_check
    self.check_response(response)
  File "/root/Projects/etlX/venv/lib/python3.9/site-packages/airflow/providers/http/hooks/http.py", line 144, in check_response
    raise AirflowException(str(response.status_code) + ":" + response.reason)
airflow.exceptions.AirflowException: 429:Too Many Requests
[2025-10-14 17:51:46,583] {processor.py:653} WARNING - No viable dags retrieved from /root/Projects/etlX/airflow/dags/x_dag.py
[2025-10-14 17:51:46,598] {processor.py:161} INFO - Processing /root/Projects/etlX/airflow/dags/x_dag.py took 0.312 seconds
[2025-10-14 17:52:17,588] {processor.py:153} INFO - Started process (PID=28648) to work on /root/Projects/etlX/airflow/dags/x_dag.py
[2025-10-14 17:52:17,589] {processor.py:641} INFO - Processing file /root/Projects/etlX/airflow/dags/x_dag.py for tasks to queue
[2025-10-14 17:52:17,589] {logging_mixin.py:115} INFO - [2025-10-14 17:52:17,589] {dagbag.py:507} INFO - Filling up the DagBag from /root/Projects/etlX/airflow/dags/x_dag.py
[2025-10-14 17:52:17,621] {logging_mixin.py:115} INFO - [2025-10-14 17:52:17,621] {base.py:68} INFO - Using connection ID 'x_default' for task execution.
[2025-10-14 17:52:17,625] {logging_mixin.py:115} INFO - [2025-10-14 17:52:17,625] {x_hook.py:40} INFO - Requisição: https://api.twitter.com/2/tweets/search/recent?query=datascience&tweet.fields=author_id,conversation_id,created_at,id,in_reply_to_user_id,public_metrics,lang,text&expansions=author_id&user.fields=id,name,username,created_at&start_time=2025-10-13T17:52:17.00Z&end_time=2025-10-14T17:52:17.00Z
[2025-10-14 17:52:17,873] {logging_mixin.py:115} INFO - [2025-10-14 17:52:17,873] {http.py:142} ERROR - HTTP error: Too Many Requests
[2025-10-14 17:52:17,874] {logging_mixin.py:115} INFO - [2025-10-14 17:52:17,874] {http.py:143} ERROR - {"title":"Too Many Requests","detail":"Too Many Requests","type":"about:blank","status":429}
[2025-10-14 17:52:17,876] {logging_mixin.py:115} INFO - [2025-10-14 17:52:17,874] {dagbag.py:320} ERROR - Failed to import: /root/Projects/etlX/airflow/dags/x_dag.py
Traceback (most recent call last):
  File "/root/Projects/etlX/venv/lib/python3.9/site-packages/airflow/providers/http/hooks/http.py", line 140, in check_response
    response.raise_for_status()
  File "/root/Projects/etlX/venv/lib/python3.9/site-packages/requests/models.py", line 960, in raise_for_status
    raise HTTPError(http_error_msg, response=self)
requests.exceptions.HTTPError: 429 Client Error: Too Many Requests for url: https://api.twitter.com/2/tweets/search/recent?query=datascience&tweet.fields=author_id,conversation_id,created_at,id,in_reply_to_user_id,public_metrics,lang,text&expansions=author_id&user.fields=id,name,username,created_at&start_time=2025-10-13T17:52:17.00Z&end_time=2025-10-14T17:52:17.00Z

During handling of the above exception, another exception occurred:

Traceback (most recent call last):
  File "/root/Projects/etlX/venv/lib/python3.9/site-packages/airflow/models/dagbag.py", line 317, in parse
    loader.exec_module(new_module)
  File "<frozen importlib._bootstrap_external>", line 855, in exec_module
  File "<frozen importlib._bootstrap>", line 228, in _call_with_frames_removed
  File "/root/Projects/etlX/airflow/dags/x_dag.py", line 22, in <module>
    x_operator.execute(ti.task_id)
  File "/root/Projects/etlX/airflow/operators/x_operator.py", line 34, in execute
    for pg in XHook(end_time, start_time, query).run():
  File "/root/Projects/etlX/airflow/hook/x_hook.py", line 68, in run
    return self.pagination(url_raw, session)
  File "/root/Projects/etlX/airflow/hook/x_hook.py", line 47, in pagination
    response = self.conn_to_endpoint(url_raw, session)
  File "/root/Projects/etlX/airflow/hook/x_hook.py", line 42, in conn_to_endpoint
    response = self.run_and_check(session, prep, {})
  File "/root/Projects/etlX/venv/lib/python3.9/site-packages/airflow/providers/http/hooks/http.py", line 183, in run_and_check
    self.check_response(response)
  File "/root/Projects/etlX/venv/lib/python3.9/site-packages/airflow/providers/http/hooks/http.py", line 144, in check_response
    raise AirflowException(str(response.status_code) + ":" + response.reason)
airflow.exceptions.AirflowException: 429:Too Many Requests
[2025-10-14 17:52:17,877] {processor.py:653} WARNING - No viable dags retrieved from /root/Projects/etlX/airflow/dags/x_dag.py
[2025-10-14 17:52:17,894] {processor.py:161} INFO - Processing /root/Projects/etlX/airflow/dags/x_dag.py took 0.312 seconds
[2025-10-14 17:52:36,537] {processor.py:153} INFO - Started process (PID=28751) to work on /root/Projects/etlX/airflow/dags/x_dag.py
[2025-10-14 17:52:36,538] {processor.py:641} INFO - Processing file /root/Projects/etlX/airflow/dags/x_dag.py for tasks to queue
[2025-10-14 17:52:36,540] {logging_mixin.py:115} INFO - [2025-10-14 17:52:36,538] {dagbag.py:507} INFO - Filling up the DagBag from /root/Projects/etlX/airflow/dags/x_dag.py
[2025-10-14 17:52:36,591] {logging_mixin.py:115} INFO - [2025-10-14 17:52:36,591] {base.py:68} INFO - Using connection ID 'x_default' for task execution.
[2025-10-14 17:52:36,595] {logging_mixin.py:115} INFO - [2025-10-14 17:52:36,595] {x_hook.py:40} INFO - Requisição: https://api.twitter.com/2/tweets/search/recent?query=datascience&tweet.fields=author_id,conversation_id,created_at,id,in_reply_to_user_id,public_metrics,lang,text&expansions=author_id&user.fields=id,name,username,created_at&start_time=2025-10-13T17:52:36.00Z&end_time=2025-10-14T17:52:36.00Z
[2025-10-14 17:52:36,833] {logging_mixin.py:115} INFO - [2025-10-14 17:52:36,833] {http.py:142} ERROR - HTTP error: Too Many Requests
[2025-10-14 17:52:36,833] {logging_mixin.py:115} INFO - [2025-10-14 17:52:36,833] {http.py:143} ERROR - {"title":"Too Many Requests","detail":"Too Many Requests","type":"about:blank","status":429}
[2025-10-14 17:52:36,835] {logging_mixin.py:115} INFO - [2025-10-14 17:52:36,833] {dagbag.py:320} ERROR - Failed to import: /root/Projects/etlX/airflow/dags/x_dag.py
Traceback (most recent call last):
  File "/root/Projects/etlX/venv/lib/python3.9/site-packages/airflow/providers/http/hooks/http.py", line 140, in check_response
    response.raise_for_status()
  File "/root/Projects/etlX/venv/lib/python3.9/site-packages/requests/models.py", line 960, in raise_for_status
    raise HTTPError(http_error_msg, response=self)
requests.exceptions.HTTPError: 429 Client Error: Too Many Requests for url: https://api.twitter.com/2/tweets/search/recent?query=datascience&tweet.fields=author_id,conversation_id,created_at,id,in_reply_to_user_id,public_metrics,lang,text&expansions=author_id&user.fields=id,name,username,created_at&start_time=2025-10-13T17:52:36.00Z&end_time=2025-10-14T17:52:36.00Z

During handling of the above exception, another exception occurred:

Traceback (most recent call last):
  File "/root/Projects/etlX/venv/lib/python3.9/site-packages/airflow/models/dagbag.py", line 317, in parse
    loader.exec_module(new_module)
  File "<frozen importlib._bootstrap_external>", line 855, in exec_module
  File "<frozen importlib._bootstrap>", line 228, in _call_with_frames_removed
  File "/root/Projects/etlX/airflow/dags/x_dag.py", line 22, in <module>
    x_operator.execute(ti.task_id)
  File "/root/Projects/etlX/airflow/operators/x_operator.py", line 34, in execute
    for pg in XHook(end_time, start_time, query).run():
  File "/root/Projects/etlX/airflow/hook/x_hook.py", line 68, in run
    return self.pagination(url_raw, session)
  File "/root/Projects/etlX/airflow/hook/x_hook.py", line 47, in pagination
    response = self.conn_to_endpoint(url_raw, session)
  File "/root/Projects/etlX/airflow/hook/x_hook.py", line 42, in conn_to_endpoint
    response = self.run_and_check(session, prep, {})
  File "/root/Projects/etlX/venv/lib/python3.9/site-packages/airflow/providers/http/hooks/http.py", line 183, in run_and_check
    self.check_response(response)
  File "/root/Projects/etlX/venv/lib/python3.9/site-packages/airflow/providers/http/hooks/http.py", line 144, in check_response
    raise AirflowException(str(response.status_code) + ":" + response.reason)
airflow.exceptions.AirflowException: 429:Too Many Requests
[2025-10-14 17:52:36,836] {processor.py:653} WARNING - No viable dags retrieved from /root/Projects/etlX/airflow/dags/x_dag.py
[2025-10-14 17:52:36,848] {processor.py:161} INFO - Processing /root/Projects/etlX/airflow/dags/x_dag.py took 0.320 seconds
[2025-10-14 17:53:07,748] {processor.py:153} INFO - Started process (PID=28880) to work on /root/Projects/etlX/airflow/dags/x_dag.py
[2025-10-14 17:53:07,749] {processor.py:641} INFO - Processing file /root/Projects/etlX/airflow/dags/x_dag.py for tasks to queue
[2025-10-14 17:53:07,749] {logging_mixin.py:115} INFO - [2025-10-14 17:53:07,749] {dagbag.py:507} INFO - Filling up the DagBag from /root/Projects/etlX/airflow/dags/x_dag.py
[2025-10-14 17:53:07,784] {logging_mixin.py:115} INFO - [2025-10-14 17:53:07,784] {base.py:68} INFO - Using connection ID 'x_default' for task execution.
[2025-10-14 17:53:07,789] {logging_mixin.py:115} INFO - [2025-10-14 17:53:07,789] {x_hook.py:40} INFO - Requisição: https://api.twitter.com/2/tweets/search/recent?query=datascience&tweet.fields=author_id,conversation_id,created_at,id,in_reply_to_user_id,public_metrics,lang,text&expansions=author_id&user.fields=id,name,username,created_at&start_time=2025-10-13T17:53:07.00Z&end_time=2025-10-14T17:53:07.00Z
[2025-10-14 17:53:08,042] {logging_mixin.py:115} INFO - [2025-10-14 17:53:08,041] {http.py:142} ERROR - HTTP error: Too Many Requests
[2025-10-14 17:53:08,042] {logging_mixin.py:115} INFO - [2025-10-14 17:53:08,042] {http.py:143} ERROR - {"title":"Too Many Requests","detail":"Too Many Requests","type":"about:blank","status":429}
[2025-10-14 17:53:08,044] {logging_mixin.py:115} INFO - [2025-10-14 17:53:08,042] {dagbag.py:320} ERROR - Failed to import: /root/Projects/etlX/airflow/dags/x_dag.py
Traceback (most recent call last):
  File "/root/Projects/etlX/venv/lib/python3.9/site-packages/airflow/providers/http/hooks/http.py", line 140, in check_response
    response.raise_for_status()
  File "/root/Projects/etlX/venv/lib/python3.9/site-packages/requests/models.py", line 960, in raise_for_status
    raise HTTPError(http_error_msg, response=self)
requests.exceptions.HTTPError: 429 Client Error: Too Many Requests for url: https://api.twitter.com/2/tweets/search/recent?query=datascience&tweet.fields=author_id,conversation_id,created_at,id,in_reply_to_user_id,public_metrics,lang,text&expansions=author_id&user.fields=id,name,username,created_at&start_time=2025-10-13T17:53:07.00Z&end_time=2025-10-14T17:53:07.00Z

During handling of the above exception, another exception occurred:

Traceback (most recent call last):
  File "/root/Projects/etlX/venv/lib/python3.9/site-packages/airflow/models/dagbag.py", line 317, in parse
    loader.exec_module(new_module)
  File "<frozen importlib._bootstrap_external>", line 855, in exec_module
  File "<frozen importlib._bootstrap>", line 228, in _call_with_frames_removed
  File "/root/Projects/etlX/airflow/dags/x_dag.py", line 22, in <module>
    x_operator.execute(ti.task_id)
  File "/root/Projects/etlX/airflow/operators/x_operator.py", line 34, in execute
    for pg in XHook(end_time, start_time, query).run():
  File "/root/Projects/etlX/airflow/hook/x_hook.py", line 68, in run
    return self.pagination(url_raw, session)
  File "/root/Projects/etlX/airflow/hook/x_hook.py", line 47, in pagination
    response = self.conn_to_endpoint(url_raw, session)
  File "/root/Projects/etlX/airflow/hook/x_hook.py", line 42, in conn_to_endpoint
    response = self.run_and_check(session, prep, {})
  File "/root/Projects/etlX/venv/lib/python3.9/site-packages/airflow/providers/http/hooks/http.py", line 183, in run_and_check
    self.check_response(response)
  File "/root/Projects/etlX/venv/lib/python3.9/site-packages/airflow/providers/http/hooks/http.py", line 144, in check_response
    raise AirflowException(str(response.status_code) + ":" + response.reason)
airflow.exceptions.AirflowException: 429:Too Many Requests
[2025-10-14 17:53:08,045] {processor.py:653} WARNING - No viable dags retrieved from /root/Projects/etlX/airflow/dags/x_dag.py
[2025-10-14 17:53:08,056] {processor.py:161} INFO - Processing /root/Projects/etlX/airflow/dags/x_dag.py took 0.314 seconds
[2025-10-14 17:53:39,022] {processor.py:153} INFO - Started process (PID=29007) to work on /root/Projects/etlX/airflow/dags/x_dag.py
[2025-10-14 17:53:39,023] {processor.py:641} INFO - Processing file /root/Projects/etlX/airflow/dags/x_dag.py for tasks to queue
[2025-10-14 17:53:39,023] {logging_mixin.py:115} INFO - [2025-10-14 17:53:39,023] {dagbag.py:507} INFO - Filling up the DagBag from /root/Projects/etlX/airflow/dags/x_dag.py
[2025-10-14 17:53:39,062] {logging_mixin.py:115} INFO - [2025-10-14 17:53:39,062] {base.py:68} INFO - Using connection ID 'x_default' for task execution.
[2025-10-14 17:53:39,066] {logging_mixin.py:115} INFO - [2025-10-14 17:53:39,066] {x_hook.py:40} INFO - Requisição: https://api.twitter.com/2/tweets/search/recent?query=datascience&tweet.fields=author_id,conversation_id,created_at,id,in_reply_to_user_id,public_metrics,lang,text&expansions=author_id&user.fields=id,name,username,created_at&start_time=2025-10-13T17:53:39.00Z&end_time=2025-10-14T17:53:39.00Z
[2025-10-14 17:53:39,325] {logging_mixin.py:115} INFO - [2025-10-14 17:53:39,325] {http.py:142} ERROR - HTTP error: Too Many Requests
[2025-10-14 17:53:39,325] {logging_mixin.py:115} INFO - [2025-10-14 17:53:39,325] {http.py:143} ERROR - {"title":"Too Many Requests","detail":"Too Many Requests","type":"about:blank","status":429}
[2025-10-14 17:53:39,329] {logging_mixin.py:115} INFO - [2025-10-14 17:53:39,325] {dagbag.py:320} ERROR - Failed to import: /root/Projects/etlX/airflow/dags/x_dag.py
Traceback (most recent call last):
  File "/root/Projects/etlX/venv/lib/python3.9/site-packages/airflow/providers/http/hooks/http.py", line 140, in check_response
    response.raise_for_status()
  File "/root/Projects/etlX/venv/lib/python3.9/site-packages/requests/models.py", line 960, in raise_for_status
    raise HTTPError(http_error_msg, response=self)
requests.exceptions.HTTPError: 429 Client Error: Too Many Requests for url: https://api.twitter.com/2/tweets/search/recent?query=datascience&tweet.fields=author_id,conversation_id,created_at,id,in_reply_to_user_id,public_metrics,lang,text&expansions=author_id&user.fields=id,name,username,created_at&start_time=2025-10-13T17:53:39.00Z&end_time=2025-10-14T17:53:39.00Z

During handling of the above exception, another exception occurred:

Traceback (most recent call last):
  File "/root/Projects/etlX/venv/lib/python3.9/site-packages/airflow/models/dagbag.py", line 317, in parse
    loader.exec_module(new_module)
  File "<frozen importlib._bootstrap_external>", line 855, in exec_module
  File "<frozen importlib._bootstrap>", line 228, in _call_with_frames_removed
  File "/root/Projects/etlX/airflow/dags/x_dag.py", line 22, in <module>
    x_operator.execute(ti.task_id)
  File "/root/Projects/etlX/airflow/operators/x_operator.py", line 34, in execute
    for pg in XHook(end_time, start_time, query).run():
  File "/root/Projects/etlX/airflow/hook/x_hook.py", line 68, in run
    return self.pagination(url_raw, session)
  File "/root/Projects/etlX/airflow/hook/x_hook.py", line 47, in pagination
    response = self.conn_to_endpoint(url_raw, session)
  File "/root/Projects/etlX/airflow/hook/x_hook.py", line 42, in conn_to_endpoint
    response = self.run_and_check(session, prep, {})
  File "/root/Projects/etlX/venv/lib/python3.9/site-packages/airflow/providers/http/hooks/http.py", line 183, in run_and_check
    self.check_response(response)
  File "/root/Projects/etlX/venv/lib/python3.9/site-packages/airflow/providers/http/hooks/http.py", line 144, in check_response
    raise AirflowException(str(response.status_code) + ":" + response.reason)
airflow.exceptions.AirflowException: 429:Too Many Requests
[2025-10-14 17:53:39,330] {processor.py:653} WARNING - No viable dags retrieved from /root/Projects/etlX/airflow/dags/x_dag.py
[2025-10-14 17:53:39,345] {processor.py:161} INFO - Processing /root/Projects/etlX/airflow/dags/x_dag.py took 0.329 seconds
[2025-10-14 17:54:10,253] {processor.py:153} INFO - Started process (PID=29083) to work on /root/Projects/etlX/airflow/dags/x_dag.py
[2025-10-14 17:54:10,254] {processor.py:641} INFO - Processing file /root/Projects/etlX/airflow/dags/x_dag.py for tasks to queue
[2025-10-14 17:54:10,255] {logging_mixin.py:115} INFO - [2025-10-14 17:54:10,254] {dagbag.py:507} INFO - Filling up the DagBag from /root/Projects/etlX/airflow/dags/x_dag.py
[2025-10-14 17:54:10,300] {logging_mixin.py:115} INFO - [2025-10-14 17:54:10,300] {base.py:68} INFO - Using connection ID 'x_default' for task execution.
[2025-10-14 17:54:10,304] {logging_mixin.py:115} INFO - [2025-10-14 17:54:10,304] {x_hook.py:40} INFO - Requisição: https://api.twitter.com/2/tweets/search/recent?query=datascience&tweet.fields=author_id,conversation_id,created_at,id,in_reply_to_user_id,public_metrics,lang,text&expansions=author_id&user.fields=id,name,username,created_at&start_time=2025-10-13T17:54:10.00Z&end_time=2025-10-14T17:54:10.00Z
[2025-10-14 17:54:10,554] {logging_mixin.py:115} INFO - [2025-10-14 17:54:10,554] {http.py:142} ERROR - HTTP error: Too Many Requests
[2025-10-14 17:54:10,555] {logging_mixin.py:115} INFO - [2025-10-14 17:54:10,555] {http.py:143} ERROR - {"title":"Too Many Requests","detail":"Too Many Requests","type":"about:blank","status":429}
[2025-10-14 17:54:10,557] {logging_mixin.py:115} INFO - [2025-10-14 17:54:10,555] {dagbag.py:320} ERROR - Failed to import: /root/Projects/etlX/airflow/dags/x_dag.py
Traceback (most recent call last):
  File "/root/Projects/etlX/venv/lib/python3.9/site-packages/airflow/providers/http/hooks/http.py", line 140, in check_response
    response.raise_for_status()
  File "/root/Projects/etlX/venv/lib/python3.9/site-packages/requests/models.py", line 960, in raise_for_status
    raise HTTPError(http_error_msg, response=self)
requests.exceptions.HTTPError: 429 Client Error: Too Many Requests for url: https://api.twitter.com/2/tweets/search/recent?query=datascience&tweet.fields=author_id,conversation_id,created_at,id,in_reply_to_user_id,public_metrics,lang,text&expansions=author_id&user.fields=id,name,username,created_at&start_time=2025-10-13T17:54:10.00Z&end_time=2025-10-14T17:54:10.00Z

During handling of the above exception, another exception occurred:

Traceback (most recent call last):
  File "/root/Projects/etlX/venv/lib/python3.9/site-packages/airflow/models/dagbag.py", line 317, in parse
    loader.exec_module(new_module)
  File "<frozen importlib._bootstrap_external>", line 855, in exec_module
  File "<frozen importlib._bootstrap>", line 228, in _call_with_frames_removed
  File "/root/Projects/etlX/airflow/dags/x_dag.py", line 22, in <module>
    x_operator.execute(ti.task_id)
  File "/root/Projects/etlX/airflow/operators/x_operator.py", line 34, in execute
    for pg in XHook(end_time, start_time, query).run():
  File "/root/Projects/etlX/airflow/hook/x_hook.py", line 68, in run
    return self.pagination(url_raw, session)
  File "/root/Projects/etlX/airflow/hook/x_hook.py", line 47, in pagination
    response = self.conn_to_endpoint(url_raw, session)
  File "/root/Projects/etlX/airflow/hook/x_hook.py", line 42, in conn_to_endpoint
    response = self.run_and_check(session, prep, {})
  File "/root/Projects/etlX/venv/lib/python3.9/site-packages/airflow/providers/http/hooks/http.py", line 183, in run_and_check
    self.check_response(response)
  File "/root/Projects/etlX/venv/lib/python3.9/site-packages/airflow/providers/http/hooks/http.py", line 144, in check_response
    raise AirflowException(str(response.status_code) + ":" + response.reason)
airflow.exceptions.AirflowException: 429:Too Many Requests
[2025-10-14 17:54:10,559] {processor.py:653} WARNING - No viable dags retrieved from /root/Projects/etlX/airflow/dags/x_dag.py
[2025-10-14 17:54:10,573] {processor.py:161} INFO - Processing /root/Projects/etlX/airflow/dags/x_dag.py took 0.326 seconds
[2025-10-14 17:54:33,750] {processor.py:153} INFO - Started process (PID=29191) to work on /root/Projects/etlX/airflow/dags/x_dag.py
[2025-10-14 17:54:33,751] {processor.py:641} INFO - Processing file /root/Projects/etlX/airflow/dags/x_dag.py for tasks to queue
[2025-10-14 17:54:33,754] {logging_mixin.py:115} INFO - [2025-10-14 17:54:33,752] {dagbag.py:507} INFO - Filling up the DagBag from /root/Projects/etlX/airflow/dags/x_dag.py
[2025-10-14 17:54:33,804] {logging_mixin.py:115} INFO - [2025-10-14 17:54:33,803] {base.py:68} INFO - Using connection ID 'x_default' for task execution.
[2025-10-14 17:54:33,807] {logging_mixin.py:115} INFO - [2025-10-14 17:54:33,807] {x_hook.py:40} INFO - Requisição: https://api.twitter.com/2/tweets/search/recent?query=datascience&tweet.fields=author_id,conversation_id,created_at,id,in_reply_to_user_id,public_metrics,lang,text&expansions=author_id&user.fields=id,name,username,created_at&start_time=2025-10-13T17:54:33.00Z&end_time=2025-10-14T17:54:33.00Z
[2025-10-14 17:54:34,044] {logging_mixin.py:115} INFO - [2025-10-14 17:54:34,044] {http.py:142} ERROR - HTTP error: Too Many Requests
[2025-10-14 17:54:34,045] {logging_mixin.py:115} INFO - [2025-10-14 17:54:34,045] {http.py:143} ERROR - {"title":"Too Many Requests","detail":"Too Many Requests","type":"about:blank","status":429}
[2025-10-14 17:54:34,046] {logging_mixin.py:115} INFO - [2025-10-14 17:54:34,045] {dagbag.py:320} ERROR - Failed to import: /root/Projects/etlX/airflow/dags/x_dag.py
Traceback (most recent call last):
  File "/root/Projects/etlX/venv/lib/python3.9/site-packages/airflow/providers/http/hooks/http.py", line 140, in check_response
    response.raise_for_status()
  File "/root/Projects/etlX/venv/lib/python3.9/site-packages/requests/models.py", line 960, in raise_for_status
    raise HTTPError(http_error_msg, response=self)
requests.exceptions.HTTPError: 429 Client Error: Too Many Requests for url: https://api.twitter.com/2/tweets/search/recent?query=datascience&tweet.fields=author_id,conversation_id,created_at,id,in_reply_to_user_id,public_metrics,lang,text&expansions=author_id&user.fields=id,name,username,created_at&start_time=2025-10-13T17:54:33.00Z&end_time=2025-10-14T17:54:33.00Z

During handling of the above exception, another exception occurred:

Traceback (most recent call last):
  File "/root/Projects/etlX/venv/lib/python3.9/site-packages/airflow/models/dagbag.py", line 317, in parse
    loader.exec_module(new_module)
  File "<frozen importlib._bootstrap_external>", line 855, in exec_module
  File "<frozen importlib._bootstrap>", line 228, in _call_with_frames_removed
  File "/root/Projects/etlX/airflow/dags/x_dag.py", line 22, in <module>
    x_operator.execute(ti.task_id)
  File "/root/Projects/etlX/airflow/operators/x_operator.py", line 34, in execute
    for pg in XHook(end_time, start_time, query).run():
  File "/root/Projects/etlX/airflow/hook/x_hook.py", line 68, in run
    return self.pagination(url_raw, session)
  File "/root/Projects/etlX/airflow/hook/x_hook.py", line 47, in pagination
    response = self.conn_to_endpoint(url_raw, session)
  File "/root/Projects/etlX/airflow/hook/x_hook.py", line 42, in conn_to_endpoint
    response = self.run_and_check(session, prep, {})
  File "/root/Projects/etlX/venv/lib/python3.9/site-packages/airflow/providers/http/hooks/http.py", line 183, in run_and_check
    self.check_response(response)
  File "/root/Projects/etlX/venv/lib/python3.9/site-packages/airflow/providers/http/hooks/http.py", line 144, in check_response
    raise AirflowException(str(response.status_code) + ":" + response.reason)
airflow.exceptions.AirflowException: 429:Too Many Requests
[2025-10-14 17:54:34,048] {processor.py:653} WARNING - No viable dags retrieved from /root/Projects/etlX/airflow/dags/x_dag.py
[2025-10-14 17:54:34,059] {processor.py:161} INFO - Processing /root/Projects/etlX/airflow/dags/x_dag.py took 0.315 seconds
[2025-10-14 17:55:04,924] {processor.py:153} INFO - Started process (PID=29370) to work on /root/Projects/etlX/airflow/dags/x_dag.py
[2025-10-14 17:55:04,924] {processor.py:641} INFO - Processing file /root/Projects/etlX/airflow/dags/x_dag.py for tasks to queue
[2025-10-14 17:55:04,925] {logging_mixin.py:115} INFO - [2025-10-14 17:55:04,925] {dagbag.py:507} INFO - Filling up the DagBag from /root/Projects/etlX/airflow/dags/x_dag.py
[2025-10-14 17:55:04,953] {logging_mixin.py:115} INFO - [2025-10-14 17:55:04,953] {base.py:68} INFO - Using connection ID 'x_default' for task execution.
[2025-10-14 17:55:04,957] {logging_mixin.py:115} INFO - [2025-10-14 17:55:04,957] {x_hook.py:40} INFO - Requisição: https://api.twitter.com/2/tweets/search/recent?query=datascience&tweet.fields=author_id,conversation_id,created_at,id,in_reply_to_user_id,public_metrics,lang,text&expansions=author_id&user.fields=id,name,username,created_at&start_time=2025-10-13T17:55:04.00Z&end_time=2025-10-14T17:55:04.00Z
[2025-10-14 17:55:05,394] {logging_mixin.py:115} INFO - [2025-10-14 17:55:05,394] {http.py:142} ERROR - HTTP error: Too Many Requests
[2025-10-14 17:55:05,395] {logging_mixin.py:115} INFO - [2025-10-14 17:55:05,394] {http.py:143} ERROR - {"title":"Too Many Requests","detail":"Too Many Requests","type":"about:blank","status":429}
[2025-10-14 17:55:05,397] {logging_mixin.py:115} INFO - [2025-10-14 17:55:05,395] {dagbag.py:320} ERROR - Failed to import: /root/Projects/etlX/airflow/dags/x_dag.py
Traceback (most recent call last):
  File "/root/Projects/etlX/venv/lib/python3.9/site-packages/airflow/providers/http/hooks/http.py", line 140, in check_response
    response.raise_for_status()
  File "/root/Projects/etlX/venv/lib/python3.9/site-packages/requests/models.py", line 960, in raise_for_status
    raise HTTPError(http_error_msg, response=self)
requests.exceptions.HTTPError: 429 Client Error: Too Many Requests for url: https://api.twitter.com/2/tweets/search/recent?query=datascience&tweet.fields=author_id,conversation_id,created_at,id,in_reply_to_user_id,public_metrics,lang,text&expansions=author_id&user.fields=id,name,username,created_at&start_time=2025-10-13T17:55:04.00Z&end_time=2025-10-14T17:55:04.00Z

During handling of the above exception, another exception occurred:

Traceback (most recent call last):
  File "/root/Projects/etlX/venv/lib/python3.9/site-packages/airflow/models/dagbag.py", line 317, in parse
    loader.exec_module(new_module)
  File "<frozen importlib._bootstrap_external>", line 855, in exec_module
  File "<frozen importlib._bootstrap>", line 228, in _call_with_frames_removed
  File "/root/Projects/etlX/airflow/dags/x_dag.py", line 22, in <module>
    x_operator.execute(ti.task_id)
  File "/root/Projects/etlX/airflow/operators/x_operator.py", line 34, in execute
    for pg in XHook(end_time, start_time, query).run():
  File "/root/Projects/etlX/airflow/hook/x_hook.py", line 68, in run
    return self.pagination(url_raw, session)
  File "/root/Projects/etlX/airflow/hook/x_hook.py", line 47, in pagination
    response = self.conn_to_endpoint(url_raw, session)
  File "/root/Projects/etlX/airflow/hook/x_hook.py", line 42, in conn_to_endpoint
    response = self.run_and_check(session, prep, {})
  File "/root/Projects/etlX/venv/lib/python3.9/site-packages/airflow/providers/http/hooks/http.py", line 183, in run_and_check
    self.check_response(response)
  File "/root/Projects/etlX/venv/lib/python3.9/site-packages/airflow/providers/http/hooks/http.py", line 144, in check_response
    raise AirflowException(str(response.status_code) + ":" + response.reason)
airflow.exceptions.AirflowException: 429:Too Many Requests
[2025-10-14 17:55:05,399] {processor.py:653} WARNING - No viable dags retrieved from /root/Projects/etlX/airflow/dags/x_dag.py
[2025-10-14 17:55:05,414] {processor.py:161} INFO - Processing /root/Projects/etlX/airflow/dags/x_dag.py took 0.494 seconds
[2025-10-14 17:55:42,025] {processor.py:153} INFO - Started process (PID=29507) to work on /root/Projects/etlX/airflow/dags/x_dag.py
[2025-10-14 17:55:42,025] {processor.py:641} INFO - Processing file /root/Projects/etlX/airflow/dags/x_dag.py for tasks to queue
[2025-10-14 17:55:42,028] {logging_mixin.py:115} INFO - [2025-10-14 17:55:42,027] {dagbag.py:507} INFO - Filling up the DagBag from /root/Projects/etlX/airflow/dags/x_dag.py
[2025-10-14 17:55:42,062] {logging_mixin.py:115} INFO - [2025-10-14 17:55:42,061] {base.py:68} INFO - Using connection ID 'x_default' for task execution.
[2025-10-14 17:55:42,066] {logging_mixin.py:115} INFO - [2025-10-14 17:55:42,066] {x_hook.py:40} INFO - Requisição: https://api.twitter.com/2/tweets/search/recent?query=datascience&tweet.fields=author_id,conversation_id,created_at,id,in_reply_to_user_id,public_metrics,lang,text&expansions=author_id&user.fields=id,name,username,created_at&start_time=2025-10-13T17:55:42.00Z&end_time=2025-10-14T17:55:42.00Z
[2025-10-14 17:55:42,343] {logging_mixin.py:115} INFO - [2025-10-14 17:55:42,342] {http.py:142} ERROR - HTTP error: Too Many Requests
[2025-10-14 17:55:42,343] {logging_mixin.py:115} INFO - [2025-10-14 17:55:42,343] {http.py:143} ERROR - {"title":"Too Many Requests","detail":"Too Many Requests","type":"about:blank","status":429}
[2025-10-14 17:55:42,344] {logging_mixin.py:115} INFO - [2025-10-14 17:55:42,343] {dagbag.py:320} ERROR - Failed to import: /root/Projects/etlX/airflow/dags/x_dag.py
Traceback (most recent call last):
  File "/root/Projects/etlX/venv/lib/python3.9/site-packages/airflow/providers/http/hooks/http.py", line 140, in check_response
    response.raise_for_status()
  File "/root/Projects/etlX/venv/lib/python3.9/site-packages/requests/models.py", line 960, in raise_for_status
    raise HTTPError(http_error_msg, response=self)
requests.exceptions.HTTPError: 429 Client Error: Too Many Requests for url: https://api.twitter.com/2/tweets/search/recent?query=datascience&tweet.fields=author_id,conversation_id,created_at,id,in_reply_to_user_id,public_metrics,lang,text&expansions=author_id&user.fields=id,name,username,created_at&start_time=2025-10-13T17:55:42.00Z&end_time=2025-10-14T17:55:42.00Z

During handling of the above exception, another exception occurred:

Traceback (most recent call last):
  File "/root/Projects/etlX/venv/lib/python3.9/site-packages/airflow/models/dagbag.py", line 317, in parse
    loader.exec_module(new_module)
  File "<frozen importlib._bootstrap_external>", line 855, in exec_module
  File "<frozen importlib._bootstrap>", line 228, in _call_with_frames_removed
  File "/root/Projects/etlX/airflow/dags/x_dag.py", line 22, in <module>
    x_operator.execute(ti.task_id)
  File "/root/Projects/etlX/airflow/operators/x_operator.py", line 34, in execute
    for pg in XHook(end_time, start_time, query).run():
  File "/root/Projects/etlX/airflow/hook/x_hook.py", line 68, in run
    return self.pagination(url_raw, session)
  File "/root/Projects/etlX/airflow/hook/x_hook.py", line 47, in pagination
    response = self.conn_to_endpoint(url_raw, session)
  File "/root/Projects/etlX/airflow/hook/x_hook.py", line 42, in conn_to_endpoint
    response = self.run_and_check(session, prep, {})
  File "/root/Projects/etlX/venv/lib/python3.9/site-packages/airflow/providers/http/hooks/http.py", line 183, in run_and_check
    self.check_response(response)
  File "/root/Projects/etlX/venv/lib/python3.9/site-packages/airflow/providers/http/hooks/http.py", line 144, in check_response
    raise AirflowException(str(response.status_code) + ":" + response.reason)
airflow.exceptions.AirflowException: 429:Too Many Requests
[2025-10-14 17:55:42,346] {processor.py:653} WARNING - No viable dags retrieved from /root/Projects/etlX/airflow/dags/x_dag.py
[2025-10-14 17:55:42,357] {processor.py:161} INFO - Processing /root/Projects/etlX/airflow/dags/x_dag.py took 0.338 seconds
[2025-10-14 17:56:13,212] {processor.py:153} INFO - Started process (PID=29670) to work on /root/Projects/etlX/airflow/dags/x_dag.py
[2025-10-14 17:56:13,213] {processor.py:641} INFO - Processing file /root/Projects/etlX/airflow/dags/x_dag.py for tasks to queue
[2025-10-14 17:56:13,213] {logging_mixin.py:115} INFO - [2025-10-14 17:56:13,213] {dagbag.py:507} INFO - Filling up the DagBag from /root/Projects/etlX/airflow/dags/x_dag.py
[2025-10-14 17:56:13,250] {logging_mixin.py:115} INFO - [2025-10-14 17:56:13,250] {base.py:68} INFO - Using connection ID 'x_default' for task execution.
[2025-10-14 17:56:13,255] {logging_mixin.py:115} INFO - [2025-10-14 17:56:13,255] {x_hook.py:40} INFO - Requisição: https://api.twitter.com/2/tweets/search/recent?query=datascience&tweet.fields=author_id,conversation_id,created_at,id,in_reply_to_user_id,public_metrics,lang,text&expansions=author_id&user.fields=id,name,username,created_at&start_time=2025-10-13T17:56:13.00Z&end_time=2025-10-14T17:56:13.00Z
[2025-10-14 17:56:13,559] {logging_mixin.py:115} INFO - [2025-10-14 17:56:13,559] {http.py:142} ERROR - HTTP error: Too Many Requests
[2025-10-14 17:56:13,562] {logging_mixin.py:115} INFO - [2025-10-14 17:56:13,562] {http.py:143} ERROR - {"title":"Too Many Requests","detail":"Too Many Requests","type":"about:blank","status":429}
[2025-10-14 17:56:13,565] {logging_mixin.py:115} INFO - [2025-10-14 17:56:13,563] {dagbag.py:320} ERROR - Failed to import: /root/Projects/etlX/airflow/dags/x_dag.py
Traceback (most recent call last):
  File "/root/Projects/etlX/venv/lib/python3.9/site-packages/airflow/providers/http/hooks/http.py", line 140, in check_response
    response.raise_for_status()
  File "/root/Projects/etlX/venv/lib/python3.9/site-packages/requests/models.py", line 960, in raise_for_status
    raise HTTPError(http_error_msg, response=self)
requests.exceptions.HTTPError: 429 Client Error: Too Many Requests for url: https://api.twitter.com/2/tweets/search/recent?query=datascience&tweet.fields=author_id,conversation_id,created_at,id,in_reply_to_user_id,public_metrics,lang,text&expansions=author_id&user.fields=id,name,username,created_at&start_time=2025-10-13T17:56:13.00Z&end_time=2025-10-14T17:56:13.00Z

During handling of the above exception, another exception occurred:

Traceback (most recent call last):
  File "/root/Projects/etlX/venv/lib/python3.9/site-packages/airflow/models/dagbag.py", line 317, in parse
    loader.exec_module(new_module)
  File "<frozen importlib._bootstrap_external>", line 855, in exec_module
  File "<frozen importlib._bootstrap>", line 228, in _call_with_frames_removed
  File "/root/Projects/etlX/airflow/dags/x_dag.py", line 22, in <module>
    x_operator.execute(ti.task_id)
  File "/root/Projects/etlX/airflow/operators/x_operator.py", line 34, in execute
    for pg in XHook(end_time, start_time, query).run():
  File "/root/Projects/etlX/airflow/hook/x_hook.py", line 68, in run
    return self.pagination(url_raw, session)
  File "/root/Projects/etlX/airflow/hook/x_hook.py", line 47, in pagination
    response = self.conn_to_endpoint(url_raw, session)
  File "/root/Projects/etlX/airflow/hook/x_hook.py", line 42, in conn_to_endpoint
    response = self.run_and_check(session, prep, {})
  File "/root/Projects/etlX/venv/lib/python3.9/site-packages/airflow/providers/http/hooks/http.py", line 183, in run_and_check
    self.check_response(response)
  File "/root/Projects/etlX/venv/lib/python3.9/site-packages/airflow/providers/http/hooks/http.py", line 144, in check_response
    raise AirflowException(str(response.status_code) + ":" + response.reason)
airflow.exceptions.AirflowException: 429:Too Many Requests
[2025-10-14 17:56:13,569] {processor.py:653} WARNING - No viable dags retrieved from /root/Projects/etlX/airflow/dags/x_dag.py
[2025-10-14 17:56:13,618] {processor.py:161} INFO - Processing /root/Projects/etlX/airflow/dags/x_dag.py took 0.411 seconds
[2025-10-14 17:56:44,519] {processor.py:153} INFO - Started process (PID=29692) to work on /root/Projects/etlX/airflow/dags/x_dag.py
[2025-10-14 17:56:44,520] {processor.py:641} INFO - Processing file /root/Projects/etlX/airflow/dags/x_dag.py for tasks to queue
[2025-10-14 17:56:44,520] {logging_mixin.py:115} INFO - [2025-10-14 17:56:44,520] {dagbag.py:507} INFO - Filling up the DagBag from /root/Projects/etlX/airflow/dags/x_dag.py
[2025-10-14 17:56:44,550] {logging_mixin.py:115} INFO - [2025-10-14 17:56:44,550] {base.py:68} INFO - Using connection ID 'x_default' for task execution.
[2025-10-14 17:56:44,553] {logging_mixin.py:115} INFO - [2025-10-14 17:56:44,553] {x_hook.py:40} INFO - Requisição: https://api.twitter.com/2/tweets/search/recent?query=datascience&tweet.fields=author_id,conversation_id,created_at,id,in_reply_to_user_id,public_metrics,lang,text&expansions=author_id&user.fields=id,name,username,created_at&start_time=2025-10-13T17:56:44.00Z&end_time=2025-10-14T17:56:44.00Z
[2025-10-14 17:56:44,802] {logging_mixin.py:115} INFO - [2025-10-14 17:56:44,802] {http.py:142} ERROR - HTTP error: Too Many Requests
[2025-10-14 17:56:44,802] {logging_mixin.py:115} INFO - [2025-10-14 17:56:44,802] {http.py:143} ERROR - {"title":"Too Many Requests","detail":"Too Many Requests","type":"about:blank","status":429}
[2025-10-14 17:56:44,804] {logging_mixin.py:115} INFO - [2025-10-14 17:56:44,802] {dagbag.py:320} ERROR - Failed to import: /root/Projects/etlX/airflow/dags/x_dag.py
Traceback (most recent call last):
  File "/root/Projects/etlX/venv/lib/python3.9/site-packages/airflow/providers/http/hooks/http.py", line 140, in check_response
    response.raise_for_status()
  File "/root/Projects/etlX/venv/lib/python3.9/site-packages/requests/models.py", line 960, in raise_for_status
    raise HTTPError(http_error_msg, response=self)
requests.exceptions.HTTPError: 429 Client Error: Too Many Requests for url: https://api.twitter.com/2/tweets/search/recent?query=datascience&tweet.fields=author_id,conversation_id,created_at,id,in_reply_to_user_id,public_metrics,lang,text&expansions=author_id&user.fields=id,name,username,created_at&start_time=2025-10-13T17:56:44.00Z&end_time=2025-10-14T17:56:44.00Z

During handling of the above exception, another exception occurred:

Traceback (most recent call last):
  File "/root/Projects/etlX/venv/lib/python3.9/site-packages/airflow/models/dagbag.py", line 317, in parse
    loader.exec_module(new_module)
  File "<frozen importlib._bootstrap_external>", line 855, in exec_module
  File "<frozen importlib._bootstrap>", line 228, in _call_with_frames_removed
  File "/root/Projects/etlX/airflow/dags/x_dag.py", line 22, in <module>
    x_operator.execute(ti.task_id)
  File "/root/Projects/etlX/airflow/operators/x_operator.py", line 34, in execute
    for pg in XHook(end_time, start_time, query).run():
  File "/root/Projects/etlX/airflow/hook/x_hook.py", line 68, in run
    return self.pagination(url_raw, session)
  File "/root/Projects/etlX/airflow/hook/x_hook.py", line 47, in pagination
    response = self.conn_to_endpoint(url_raw, session)
  File "/root/Projects/etlX/airflow/hook/x_hook.py", line 42, in conn_to_endpoint
    response = self.run_and_check(session, prep, {})
  File "/root/Projects/etlX/venv/lib/python3.9/site-packages/airflow/providers/http/hooks/http.py", line 183, in run_and_check
    self.check_response(response)
  File "/root/Projects/etlX/venv/lib/python3.9/site-packages/airflow/providers/http/hooks/http.py", line 144, in check_response
    raise AirflowException(str(response.status_code) + ":" + response.reason)
airflow.exceptions.AirflowException: 429:Too Many Requests
[2025-10-14 17:56:44,805] {processor.py:653} WARNING - No viable dags retrieved from /root/Projects/etlX/airflow/dags/x_dag.py
[2025-10-14 17:56:44,816] {processor.py:161} INFO - Processing /root/Projects/etlX/airflow/dags/x_dag.py took 0.303 seconds
[2025-10-14 17:57:46,788] {processor.py:153} INFO - Started process (PID=29840) to work on /root/Projects/etlX/airflow/dags/x_dag.py
[2025-10-14 17:57:46,789] {processor.py:641} INFO - Processing file /root/Projects/etlX/airflow/dags/x_dag.py for tasks to queue
[2025-10-14 17:57:46,790] {logging_mixin.py:115} INFO - [2025-10-14 17:57:46,790] {dagbag.py:507} INFO - Filling up the DagBag from /root/Projects/etlX/airflow/dags/x_dag.py
[2025-10-14 17:57:46,819] {logging_mixin.py:115} INFO - [2025-10-14 17:57:46,819] {base.py:68} INFO - Using connection ID 'x_default' for task execution.
[2025-10-14 17:57:46,823] {logging_mixin.py:115} INFO - [2025-10-14 17:57:46,822] {x_hook.py:40} INFO - Requisição: https://api.twitter.com/2/tweets/search/recent?query=datascience&tweet.fields=author_id,conversation_id,created_at,id,in_reply_to_user_id,public_metrics,lang,text&expansions=author_id&user.fields=id,name,username,created_at&start_time=2025-10-13T17:57:46.00Z&end_time=2025-10-14T17:57:46.00Z
[2025-10-14 17:57:47,074] {logging_mixin.py:115} INFO - [2025-10-14 17:57:47,074] {http.py:142} ERROR - HTTP error: Too Many Requests
[2025-10-14 17:57:47,074] {logging_mixin.py:115} INFO - [2025-10-14 17:57:47,074] {http.py:143} ERROR - {"title":"Too Many Requests","detail":"Too Many Requests","type":"about:blank","status":429}
[2025-10-14 17:57:47,076] {logging_mixin.py:115} INFO - [2025-10-14 17:57:47,075] {dagbag.py:320} ERROR - Failed to import: /root/Projects/etlX/airflow/dags/x_dag.py
Traceback (most recent call last):
  File "/root/Projects/etlX/venv/lib/python3.9/site-packages/airflow/providers/http/hooks/http.py", line 140, in check_response
    response.raise_for_status()
  File "/root/Projects/etlX/venv/lib/python3.9/site-packages/requests/models.py", line 960, in raise_for_status
    raise HTTPError(http_error_msg, response=self)
requests.exceptions.HTTPError: 429 Client Error: Too Many Requests for url: https://api.twitter.com/2/tweets/search/recent?query=datascience&tweet.fields=author_id,conversation_id,created_at,id,in_reply_to_user_id,public_metrics,lang,text&expansions=author_id&user.fields=id,name,username,created_at&start_time=2025-10-13T17:57:46.00Z&end_time=2025-10-14T17:57:46.00Z

During handling of the above exception, another exception occurred:

Traceback (most recent call last):
  File "/root/Projects/etlX/venv/lib/python3.9/site-packages/airflow/models/dagbag.py", line 317, in parse
    loader.exec_module(new_module)
  File "<frozen importlib._bootstrap_external>", line 855, in exec_module
  File "<frozen importlib._bootstrap>", line 228, in _call_with_frames_removed
  File "/root/Projects/etlX/airflow/dags/x_dag.py", line 22, in <module>
    x_operator.execute(ti.task_id)
  File "/root/Projects/etlX/airflow/operators/x_operator.py", line 34, in execute
    for pg in XHook(end_time, start_time, query).run():
  File "/root/Projects/etlX/airflow/hook/x_hook.py", line 68, in run
    return self.pagination(url_raw, session)
  File "/root/Projects/etlX/airflow/hook/x_hook.py", line 47, in pagination
    response = self.conn_to_endpoint(url_raw, session)
  File "/root/Projects/etlX/airflow/hook/x_hook.py", line 42, in conn_to_endpoint
    response = self.run_and_check(session, prep, {})
  File "/root/Projects/etlX/venv/lib/python3.9/site-packages/airflow/providers/http/hooks/http.py", line 183, in run_and_check
    self.check_response(response)
  File "/root/Projects/etlX/venv/lib/python3.9/site-packages/airflow/providers/http/hooks/http.py", line 144, in check_response
    raise AirflowException(str(response.status_code) + ":" + response.reason)
airflow.exceptions.AirflowException: 429:Too Many Requests
[2025-10-14 17:57:47,078] {processor.py:653} WARNING - No viable dags retrieved from /root/Projects/etlX/airflow/dags/x_dag.py
[2025-10-14 17:57:47,089] {processor.py:161} INFO - Processing /root/Projects/etlX/airflow/dags/x_dag.py took 0.305 seconds
[2025-10-14 17:58:17,975] {processor.py:153} INFO - Started process (PID=29979) to work on /root/Projects/etlX/airflow/dags/x_dag.py
[2025-10-14 17:58:17,975] {processor.py:641} INFO - Processing file /root/Projects/etlX/airflow/dags/x_dag.py for tasks to queue
[2025-10-14 17:58:17,976] {logging_mixin.py:115} INFO - [2025-10-14 17:58:17,976] {dagbag.py:507} INFO - Filling up the DagBag from /root/Projects/etlX/airflow/dags/x_dag.py
[2025-10-14 17:58:18,001] {logging_mixin.py:115} INFO - [2025-10-14 17:58:18,001] {base.py:68} INFO - Using connection ID 'x_default' for task execution.
[2025-10-14 17:58:18,005] {logging_mixin.py:115} INFO - [2025-10-14 17:58:18,004] {x_hook.py:40} INFO - Requisição: https://api.twitter.com/2/tweets/search/recent?query=datascience&tweet.fields=author_id,conversation_id,created_at,id,in_reply_to_user_id,public_metrics,lang,text&expansions=author_id&user.fields=id,name,username,created_at&start_time=2025-10-13T17:58:17.00Z&end_time=2025-10-14T17:58:17.00Z
[2025-10-14 17:58:18,249] {logging_mixin.py:115} INFO - [2025-10-14 17:58:18,249] {http.py:142} ERROR - HTTP error: Too Many Requests
[2025-10-14 17:58:18,249] {logging_mixin.py:115} INFO - [2025-10-14 17:58:18,249] {http.py:143} ERROR - {"title":"Too Many Requests","detail":"Too Many Requests","type":"about:blank","status":429}
[2025-10-14 17:58:18,253] {logging_mixin.py:115} INFO - [2025-10-14 17:58:18,249] {dagbag.py:320} ERROR - Failed to import: /root/Projects/etlX/airflow/dags/x_dag.py
Traceback (most recent call last):
  File "/root/Projects/etlX/venv/lib/python3.9/site-packages/airflow/providers/http/hooks/http.py", line 140, in check_response
    response.raise_for_status()
  File "/root/Projects/etlX/venv/lib/python3.9/site-packages/requests/models.py", line 960, in raise_for_status
    raise HTTPError(http_error_msg, response=self)
requests.exceptions.HTTPError: 429 Client Error: Too Many Requests for url: https://api.twitter.com/2/tweets/search/recent?query=datascience&tweet.fields=author_id,conversation_id,created_at,id,in_reply_to_user_id,public_metrics,lang,text&expansions=author_id&user.fields=id,name,username,created_at&start_time=2025-10-13T17:58:17.00Z&end_time=2025-10-14T17:58:17.00Z

During handling of the above exception, another exception occurred:

Traceback (most recent call last):
  File "/root/Projects/etlX/venv/lib/python3.9/site-packages/airflow/models/dagbag.py", line 317, in parse
    loader.exec_module(new_module)
  File "<frozen importlib._bootstrap_external>", line 855, in exec_module
  File "<frozen importlib._bootstrap>", line 228, in _call_with_frames_removed
  File "/root/Projects/etlX/airflow/dags/x_dag.py", line 22, in <module>
    x_operator.execute(ti.task_id)
  File "/root/Projects/etlX/airflow/operators/x_operator.py", line 34, in execute
    for pg in XHook(end_time, start_time, query).run():
  File "/root/Projects/etlX/airflow/hook/x_hook.py", line 68, in run
    return self.pagination(url_raw, session)
  File "/root/Projects/etlX/airflow/hook/x_hook.py", line 47, in pagination
    response = self.conn_to_endpoint(url_raw, session)
  File "/root/Projects/etlX/airflow/hook/x_hook.py", line 42, in conn_to_endpoint
    response = self.run_and_check(session, prep, {})
  File "/root/Projects/etlX/venv/lib/python3.9/site-packages/airflow/providers/http/hooks/http.py", line 183, in run_and_check
    self.check_response(response)
  File "/root/Projects/etlX/venv/lib/python3.9/site-packages/airflow/providers/http/hooks/http.py", line 144, in check_response
    raise AirflowException(str(response.status_code) + ":" + response.reason)
airflow.exceptions.AirflowException: 429:Too Many Requests
[2025-10-14 17:58:18,256] {processor.py:653} WARNING - No viable dags retrieved from /root/Projects/etlX/airflow/dags/x_dag.py
[2025-10-14 17:58:18,284] {processor.py:161} INFO - Processing /root/Projects/etlX/airflow/dags/x_dag.py took 0.313 seconds
[2025-10-14 17:58:49,298] {processor.py:153} INFO - Started process (PID=30001) to work on /root/Projects/etlX/airflow/dags/x_dag.py
[2025-10-14 17:58:49,299] {processor.py:641} INFO - Processing file /root/Projects/etlX/airflow/dags/x_dag.py for tasks to queue
[2025-10-14 17:58:49,299] {logging_mixin.py:115} INFO - [2025-10-14 17:58:49,299] {dagbag.py:507} INFO - Filling up the DagBag from /root/Projects/etlX/airflow/dags/x_dag.py
[2025-10-14 17:58:49,329] {logging_mixin.py:115} INFO - [2025-10-14 17:58:49,328] {base.py:68} INFO - Using connection ID 'x_default' for task execution.
[2025-10-14 17:58:49,332] {logging_mixin.py:115} INFO - [2025-10-14 17:58:49,332] {x_hook.py:40} INFO - Requisição: https://api.twitter.com/2/tweets/search/recent?query=datascience&tweet.fields=author_id,conversation_id,created_at,id,in_reply_to_user_id,public_metrics,lang,text&expansions=author_id&user.fields=id,name,username,created_at&start_time=2025-10-13T17:58:49.00Z&end_time=2025-10-14T17:58:49.00Z
[2025-10-14 17:58:49,594] {logging_mixin.py:115} INFO - [2025-10-14 17:58:49,594] {http.py:142} ERROR - HTTP error: Too Many Requests
[2025-10-14 17:58:49,594] {logging_mixin.py:115} INFO - [2025-10-14 17:58:49,594] {http.py:143} ERROR - {"title":"Too Many Requests","detail":"Too Many Requests","type":"about:blank","status":429}
[2025-10-14 17:58:49,596] {logging_mixin.py:115} INFO - [2025-10-14 17:58:49,594] {dagbag.py:320} ERROR - Failed to import: /root/Projects/etlX/airflow/dags/x_dag.py
Traceback (most recent call last):
  File "/root/Projects/etlX/venv/lib/python3.9/site-packages/airflow/providers/http/hooks/http.py", line 140, in check_response
    response.raise_for_status()
  File "/root/Projects/etlX/venv/lib/python3.9/site-packages/requests/models.py", line 960, in raise_for_status
    raise HTTPError(http_error_msg, response=self)
requests.exceptions.HTTPError: 429 Client Error: Too Many Requests for url: https://api.twitter.com/2/tweets/search/recent?query=datascience&tweet.fields=author_id,conversation_id,created_at,id,in_reply_to_user_id,public_metrics,lang,text&expansions=author_id&user.fields=id,name,username,created_at&start_time=2025-10-13T17:58:49.00Z&end_time=2025-10-14T17:58:49.00Z

During handling of the above exception, another exception occurred:

Traceback (most recent call last):
  File "/root/Projects/etlX/venv/lib/python3.9/site-packages/airflow/models/dagbag.py", line 317, in parse
    loader.exec_module(new_module)
  File "<frozen importlib._bootstrap_external>", line 855, in exec_module
  File "<frozen importlib._bootstrap>", line 228, in _call_with_frames_removed
  File "/root/Projects/etlX/airflow/dags/x_dag.py", line 22, in <module>
    x_operator.execute(ti.task_id)
  File "/root/Projects/etlX/airflow/operators/x_operator.py", line 34, in execute
    for pg in XHook(end_time, start_time, query).run():
  File "/root/Projects/etlX/airflow/hook/x_hook.py", line 68, in run
    return self.pagination(url_raw, session)
  File "/root/Projects/etlX/airflow/hook/x_hook.py", line 47, in pagination
    response = self.conn_to_endpoint(url_raw, session)
  File "/root/Projects/etlX/airflow/hook/x_hook.py", line 42, in conn_to_endpoint
    response = self.run_and_check(session, prep, {})
  File "/root/Projects/etlX/venv/lib/python3.9/site-packages/airflow/providers/http/hooks/http.py", line 183, in run_and_check
    self.check_response(response)
  File "/root/Projects/etlX/venv/lib/python3.9/site-packages/airflow/providers/http/hooks/http.py", line 144, in check_response
    raise AirflowException(str(response.status_code) + ":" + response.reason)
airflow.exceptions.AirflowException: 429:Too Many Requests
[2025-10-14 17:58:49,597] {processor.py:653} WARNING - No viable dags retrieved from /root/Projects/etlX/airflow/dags/x_dag.py
[2025-10-14 17:58:49,608] {processor.py:161} INFO - Processing /root/Projects/etlX/airflow/dags/x_dag.py took 0.314 seconds
[2025-10-14 17:59:20,588] {processor.py:153} INFO - Started process (PID=30020) to work on /root/Projects/etlX/airflow/dags/x_dag.py
[2025-10-14 17:59:20,589] {processor.py:641} INFO - Processing file /root/Projects/etlX/airflow/dags/x_dag.py for tasks to queue
[2025-10-14 17:59:20,590] {logging_mixin.py:115} INFO - [2025-10-14 17:59:20,590] {dagbag.py:507} INFO - Filling up the DagBag from /root/Projects/etlX/airflow/dags/x_dag.py
[2025-10-14 17:59:20,616] {logging_mixin.py:115} INFO - [2025-10-14 17:59:20,616] {base.py:68} INFO - Using connection ID 'x_default' for task execution.
[2025-10-14 17:59:20,619] {logging_mixin.py:115} INFO - [2025-10-14 17:59:20,619] {x_hook.py:40} INFO - Requisição: https://api.twitter.com/2/tweets/search/recent?query=datascience&tweet.fields=author_id,conversation_id,created_at,id,in_reply_to_user_id,public_metrics,lang,text&expansions=author_id&user.fields=id,name,username,created_at&start_time=2025-10-13T17:59:20.00Z&end_time=2025-10-14T17:59:20.00Z
[2025-10-14 17:59:20,899] {logging_mixin.py:115} INFO - [2025-10-14 17:59:20,899] {http.py:142} ERROR - HTTP error: Too Many Requests
[2025-10-14 17:59:20,899] {logging_mixin.py:115} INFO - [2025-10-14 17:59:20,899] {http.py:143} ERROR - {"title":"Too Many Requests","detail":"Too Many Requests","type":"about:blank","status":429}
[2025-10-14 17:59:20,901] {logging_mixin.py:115} INFO - [2025-10-14 17:59:20,899] {dagbag.py:320} ERROR - Failed to import: /root/Projects/etlX/airflow/dags/x_dag.py
Traceback (most recent call last):
  File "/root/Projects/etlX/venv/lib/python3.9/site-packages/airflow/providers/http/hooks/http.py", line 140, in check_response
    response.raise_for_status()
  File "/root/Projects/etlX/venv/lib/python3.9/site-packages/requests/models.py", line 960, in raise_for_status
    raise HTTPError(http_error_msg, response=self)
requests.exceptions.HTTPError: 429 Client Error: Too Many Requests for url: https://api.twitter.com/2/tweets/search/recent?query=datascience&tweet.fields=author_id,conversation_id,created_at,id,in_reply_to_user_id,public_metrics,lang,text&expansions=author_id&user.fields=id,name,username,created_at&start_time=2025-10-13T17:59:20.00Z&end_time=2025-10-14T17:59:20.00Z

During handling of the above exception, another exception occurred:

Traceback (most recent call last):
  File "/root/Projects/etlX/venv/lib/python3.9/site-packages/airflow/models/dagbag.py", line 317, in parse
    loader.exec_module(new_module)
  File "<frozen importlib._bootstrap_external>", line 855, in exec_module
  File "<frozen importlib._bootstrap>", line 228, in _call_with_frames_removed
  File "/root/Projects/etlX/airflow/dags/x_dag.py", line 22, in <module>
    x_operator.execute(ti.task_id)
  File "/root/Projects/etlX/airflow/operators/x_operator.py", line 34, in execute
    for pg in XHook(end_time, start_time, query).run():
  File "/root/Projects/etlX/airflow/hook/x_hook.py", line 68, in run
    return self.pagination(url_raw, session)
  File "/root/Projects/etlX/airflow/hook/x_hook.py", line 47, in pagination
    response = self.conn_to_endpoint(url_raw, session)
  File "/root/Projects/etlX/airflow/hook/x_hook.py", line 42, in conn_to_endpoint
    response = self.run_and_check(session, prep, {})
  File "/root/Projects/etlX/venv/lib/python3.9/site-packages/airflow/providers/http/hooks/http.py", line 183, in run_and_check
    self.check_response(response)
  File "/root/Projects/etlX/venv/lib/python3.9/site-packages/airflow/providers/http/hooks/http.py", line 144, in check_response
    raise AirflowException(str(response.status_code) + ":" + response.reason)
airflow.exceptions.AirflowException: 429:Too Many Requests
[2025-10-14 17:59:20,903] {processor.py:653} WARNING - No viable dags retrieved from /root/Projects/etlX/airflow/dags/x_dag.py
[2025-10-14 17:59:20,919] {processor.py:161} INFO - Processing /root/Projects/etlX/airflow/dags/x_dag.py took 0.341 seconds
[2025-10-14 17:59:51,865] {processor.py:153} INFO - Started process (PID=30042) to work on /root/Projects/etlX/airflow/dags/x_dag.py
[2025-10-14 17:59:51,866] {processor.py:641} INFO - Processing file /root/Projects/etlX/airflow/dags/x_dag.py for tasks to queue
[2025-10-14 17:59:51,866] {logging_mixin.py:115} INFO - [2025-10-14 17:59:51,866] {dagbag.py:507} INFO - Filling up the DagBag from /root/Projects/etlX/airflow/dags/x_dag.py
[2025-10-14 17:59:51,893] {logging_mixin.py:115} INFO - [2025-10-14 17:59:51,892] {base.py:68} INFO - Using connection ID 'x_default' for task execution.
[2025-10-14 17:59:51,896] {logging_mixin.py:115} INFO - [2025-10-14 17:59:51,896] {x_hook.py:40} INFO - Requisição: https://api.twitter.com/2/tweets/search/recent?query=datascience&tweet.fields=author_id,conversation_id,created_at,id,in_reply_to_user_id,public_metrics,lang,text&expansions=author_id&user.fields=id,name,username,created_at&start_time=2025-10-13T17:59:51.00Z&end_time=2025-10-14T17:59:51.00Z
[2025-10-14 17:59:52,123] {logging_mixin.py:115} INFO - [2025-10-14 17:59:52,123] {http.py:142} ERROR - HTTP error: Too Many Requests
[2025-10-14 17:59:52,123] {logging_mixin.py:115} INFO - [2025-10-14 17:59:52,123] {http.py:143} ERROR - {"title":"Too Many Requests","detail":"Too Many Requests","type":"about:blank","status":429}
[2025-10-14 17:59:52,128] {logging_mixin.py:115} INFO - [2025-10-14 17:59:52,123] {dagbag.py:320} ERROR - Failed to import: /root/Projects/etlX/airflow/dags/x_dag.py
Traceback (most recent call last):
  File "/root/Projects/etlX/venv/lib/python3.9/site-packages/airflow/providers/http/hooks/http.py", line 140, in check_response
    response.raise_for_status()
  File "/root/Projects/etlX/venv/lib/python3.9/site-packages/requests/models.py", line 960, in raise_for_status
    raise HTTPError(http_error_msg, response=self)
requests.exceptions.HTTPError: 429 Client Error: Too Many Requests for url: https://api.twitter.com/2/tweets/search/recent?query=datascience&tweet.fields=author_id,conversation_id,created_at,id,in_reply_to_user_id,public_metrics,lang,text&expansions=author_id&user.fields=id,name,username,created_at&start_time=2025-10-13T17:59:51.00Z&end_time=2025-10-14T17:59:51.00Z

During handling of the above exception, another exception occurred:

Traceback (most recent call last):
  File "/root/Projects/etlX/venv/lib/python3.9/site-packages/airflow/models/dagbag.py", line 317, in parse
    loader.exec_module(new_module)
  File "<frozen importlib._bootstrap_external>", line 855, in exec_module
  File "<frozen importlib._bootstrap>", line 228, in _call_with_frames_removed
  File "/root/Projects/etlX/airflow/dags/x_dag.py", line 22, in <module>
    x_operator.execute(ti.task_id)
  File "/root/Projects/etlX/airflow/operators/x_operator.py", line 34, in execute
    for pg in XHook(end_time, start_time, query).run():
  File "/root/Projects/etlX/airflow/hook/x_hook.py", line 68, in run
    return self.pagination(url_raw, session)
  File "/root/Projects/etlX/airflow/hook/x_hook.py", line 47, in pagination
    response = self.conn_to_endpoint(url_raw, session)
  File "/root/Projects/etlX/airflow/hook/x_hook.py", line 42, in conn_to_endpoint
    response = self.run_and_check(session, prep, {})
  File "/root/Projects/etlX/venv/lib/python3.9/site-packages/airflow/providers/http/hooks/http.py", line 183, in run_and_check
    self.check_response(response)
  File "/root/Projects/etlX/venv/lib/python3.9/site-packages/airflow/providers/http/hooks/http.py", line 144, in check_response
    raise AirflowException(str(response.status_code) + ":" + response.reason)
airflow.exceptions.AirflowException: 429:Too Many Requests
[2025-10-14 17:59:52,130] {processor.py:653} WARNING - No viable dags retrieved from /root/Projects/etlX/airflow/dags/x_dag.py
[2025-10-14 17:59:52,154] {processor.py:161} INFO - Processing /root/Projects/etlX/airflow/dags/x_dag.py took 0.292 seconds
[2025-10-14 18:02:01,822] {processor.py:153} INFO - Started process (PID=30249) to work on /root/Projects/etlX/airflow/dags/x_dag.py
[2025-10-14 18:02:01,822] {processor.py:641} INFO - Processing file /root/Projects/etlX/airflow/dags/x_dag.py for tasks to queue
[2025-10-14 18:02:01,823] {logging_mixin.py:115} INFO - [2025-10-14 18:02:01,823] {dagbag.py:507} INFO - Filling up the DagBag from /root/Projects/etlX/airflow/dags/x_dag.py
[2025-10-14 18:02:01,854] {logging_mixin.py:115} INFO - [2025-10-14 18:02:01,853] {base.py:68} INFO - Using connection ID 'x_default' for task execution.
[2025-10-14 18:02:01,857] {logging_mixin.py:115} INFO - [2025-10-14 18:02:01,857] {x_hook.py:40} INFO - Requisição: https://api.twitter.com/2/tweets/search/recent?query=datascience&tweet.fields=author_id,conversation_id,created_at,id,in_reply_to_user_id,public_metrics,lang,text&expansions=author_id&user.fields=id,name,username,created_at&start_time=2025-10-13T18:02:01.00Z&end_time=2025-10-14T18:02:01.00Z
[2025-10-14 18:02:02,113] {logging_mixin.py:115} INFO - [2025-10-14 18:02:02,112] {http.py:142} ERROR - HTTP error: Too Many Requests
[2025-10-14 18:02:02,113] {logging_mixin.py:115} INFO - [2025-10-14 18:02:02,113] {http.py:143} ERROR - {"title":"Too Many Requests","detail":"Too Many Requests","type":"about:blank","status":429}
[2025-10-14 18:02:02,115] {logging_mixin.py:115} INFO - [2025-10-14 18:02:02,113] {dagbag.py:320} ERROR - Failed to import: /root/Projects/etlX/airflow/dags/x_dag.py
Traceback (most recent call last):
  File "/root/Projects/etlX/venv/lib/python3.9/site-packages/airflow/providers/http/hooks/http.py", line 140, in check_response
    response.raise_for_status()
  File "/root/Projects/etlX/venv/lib/python3.9/site-packages/requests/models.py", line 960, in raise_for_status
    raise HTTPError(http_error_msg, response=self)
requests.exceptions.HTTPError: 429 Client Error: Too Many Requests for url: https://api.twitter.com/2/tweets/search/recent?query=datascience&tweet.fields=author_id,conversation_id,created_at,id,in_reply_to_user_id,public_metrics,lang,text&expansions=author_id&user.fields=id,name,username,created_at&start_time=2025-10-13T18:02:01.00Z&end_time=2025-10-14T18:02:01.00Z

During handling of the above exception, another exception occurred:

Traceback (most recent call last):
  File "/root/Projects/etlX/venv/lib/python3.9/site-packages/airflow/models/dagbag.py", line 317, in parse
    loader.exec_module(new_module)
  File "<frozen importlib._bootstrap_external>", line 855, in exec_module
  File "<frozen importlib._bootstrap>", line 228, in _call_with_frames_removed
  File "/root/Projects/etlX/airflow/dags/x_dag.py", line 22, in <module>
    x_operator.execute(ti.task_id)
  File "/root/Projects/etlX/airflow/operators/x_operator.py", line 34, in execute
    for pg in XHook(end_time, start_time, query).run():
  File "/root/Projects/etlX/airflow/hook/x_hook.py", line 68, in run
    return self.pagination(url_raw, session)
  File "/root/Projects/etlX/airflow/hook/x_hook.py", line 47, in pagination
    response = self.conn_to_endpoint(url_raw, session)
  File "/root/Projects/etlX/airflow/hook/x_hook.py", line 42, in conn_to_endpoint
    response = self.run_and_check(session, prep, {})
  File "/root/Projects/etlX/venv/lib/python3.9/site-packages/airflow/providers/http/hooks/http.py", line 183, in run_and_check
    self.check_response(response)
  File "/root/Projects/etlX/venv/lib/python3.9/site-packages/airflow/providers/http/hooks/http.py", line 144, in check_response
    raise AirflowException(str(response.status_code) + ":" + response.reason)
airflow.exceptions.AirflowException: 429:Too Many Requests
[2025-10-14 18:02:02,115] {processor.py:653} WARNING - No viable dags retrieved from /root/Projects/etlX/airflow/dags/x_dag.py
[2025-10-14 18:02:02,127] {processor.py:161} INFO - Processing /root/Projects/etlX/airflow/dags/x_dag.py took 0.311 seconds
[2025-10-14 18:06:01,230] {processor.py:153} INFO - Started process (PID=30628) to work on /root/Projects/etlX/airflow/dags/x_dag.py
[2025-10-14 18:06:01,232] {processor.py:641} INFO - Processing file /root/Projects/etlX/airflow/dags/x_dag.py for tasks to queue
[2025-10-14 18:06:01,232] {logging_mixin.py:115} INFO - [2025-10-14 18:06:01,232] {dagbag.py:507} INFO - Filling up the DagBag from /root/Projects/etlX/airflow/dags/x_dag.py
[2025-10-14 18:06:01,255] {processor.py:651} INFO - DAG(s) dict_keys(['x_DAG']) retrieved from /root/Projects/etlX/airflow/dags/x_dag.py
[2025-10-14 18:06:01,343] {logging_mixin.py:115} INFO - [2025-10-14 18:06:01,343] {manager.py:508} INFO - Created Permission View: can read on DAG:x_DAG
[2025-10-14 18:06:01,361] {logging_mixin.py:115} INFO - [2025-10-14 18:06:01,360] {manager.py:508} INFO - Created Permission View: can delete on DAG:x_DAG
[2025-10-14 18:06:01,371] {logging_mixin.py:115} INFO - [2025-10-14 18:06:01,371] {manager.py:508} INFO - Created Permission View: can edit on DAG:x_DAG
[2025-10-14 18:06:01,372] {logging_mixin.py:115} INFO - [2025-10-14 18:06:01,372] {dag.py:2379} INFO - Sync 1 DAGs
[2025-10-14 18:06:01,381] {logging_mixin.py:115} INFO - [2025-10-14 18:06:01,381] {dag.py:2398} INFO - Creating ORM DAG for x_DAG
[2025-10-14 18:06:01,391] {logging_mixin.py:115} INFO - [2025-10-14 18:06:01,391] {dag.py:2927} INFO - Setting next_dagrun for x_DAG to 2025-10-14T18:06:01.252018+00:00, run_after=2025-10-15T18:06:01.252018+00:00
[2025-10-14 18:06:01,405] {processor.py:161} INFO - Processing /root/Projects/etlX/airflow/dags/x_dag.py took 0.180 seconds
[2025-10-14 18:06:32,452] {processor.py:153} INFO - Started process (PID=30895) to work on /root/Projects/etlX/airflow/dags/x_dag.py
[2025-10-14 18:06:32,453] {processor.py:641} INFO - Processing file /root/Projects/etlX/airflow/dags/x_dag.py for tasks to queue
[2025-10-14 18:06:32,453] {logging_mixin.py:115} INFO - [2025-10-14 18:06:32,453] {dagbag.py:507} INFO - Filling up the DagBag from /root/Projects/etlX/airflow/dags/x_dag.py
[2025-10-14 18:06:32,468] {processor.py:651} INFO - DAG(s) dict_keys(['x_DAG']) retrieved from /root/Projects/etlX/airflow/dags/x_dag.py
[2025-10-14 18:06:32,531] {logging_mixin.py:115} INFO - [2025-10-14 18:06:32,531] {dag.py:2379} INFO - Sync 1 DAGs
[2025-10-14 18:06:32,549] {logging_mixin.py:115} INFO - [2025-10-14 18:06:32,548] {dag.py:2927} INFO - Setting next_dagrun for x_DAG to 2025-10-14T18:06:32.465452+00:00, run_after=2025-10-15T18:06:32.465452+00:00
[2025-10-14 18:06:32,563] {processor.py:161} INFO - Processing /root/Projects/etlX/airflow/dags/x_dag.py took 0.116 seconds
[2025-10-14 18:07:02,699] {processor.py:153} INFO - Started process (PID=30917) to work on /root/Projects/etlX/airflow/dags/x_dag.py
[2025-10-14 18:07:02,700] {processor.py:641} INFO - Processing file /root/Projects/etlX/airflow/dags/x_dag.py for tasks to queue
[2025-10-14 18:07:02,700] {logging_mixin.py:115} INFO - [2025-10-14 18:07:02,700] {dagbag.py:507} INFO - Filling up the DagBag from /root/Projects/etlX/airflow/dags/x_dag.py
[2025-10-14 18:07:02,714] {processor.py:651} INFO - DAG(s) dict_keys(['x_DAG']) retrieved from /root/Projects/etlX/airflow/dags/x_dag.py
[2025-10-14 18:07:02,765] {logging_mixin.py:115} INFO - [2025-10-14 18:07:02,765] {dag.py:2379} INFO - Sync 1 DAGs
[2025-10-14 18:07:02,780] {logging_mixin.py:115} INFO - [2025-10-14 18:07:02,780] {dag.py:2927} INFO - Setting next_dagrun for x_DAG to 2025-10-08T00:00:00+00:00, run_after=2025-10-09T00:00:00+00:00
[2025-10-14 18:07:02,794] {processor.py:161} INFO - Processing /root/Projects/etlX/airflow/dags/x_dag.py took 0.100 seconds
[2025-10-14 18:07:32,936] {processor.py:153} INFO - Started process (PID=30936) to work on /root/Projects/etlX/airflow/dags/x_dag.py
[2025-10-14 18:07:32,937] {processor.py:641} INFO - Processing file /root/Projects/etlX/airflow/dags/x_dag.py for tasks to queue
[2025-10-14 18:07:32,938] {logging_mixin.py:115} INFO - [2025-10-14 18:07:32,938] {dagbag.py:507} INFO - Filling up the DagBag from /root/Projects/etlX/airflow/dags/x_dag.py
[2025-10-14 18:07:32,951] {processor.py:651} INFO - DAG(s) dict_keys(['x_DAG']) retrieved from /root/Projects/etlX/airflow/dags/x_dag.py
[2025-10-14 18:07:33,011] {logging_mixin.py:115} INFO - [2025-10-14 18:07:33,011] {dag.py:2379} INFO - Sync 1 DAGs
[2025-10-14 18:07:33,026] {logging_mixin.py:115} INFO - [2025-10-14 18:07:33,026] {dag.py:2927} INFO - Setting next_dagrun for x_DAG to 2025-10-08T00:00:00+00:00, run_after=2025-10-09T00:00:00+00:00
[2025-10-14 18:07:33,038] {processor.py:161} INFO - Processing /root/Projects/etlX/airflow/dags/x_dag.py took 0.106 seconds
[2025-10-14 18:08:03,218] {processor.py:153} INFO - Started process (PID=31009) to work on /root/Projects/etlX/airflow/dags/x_dag.py
[2025-10-14 18:08:03,218] {processor.py:641} INFO - Processing file /root/Projects/etlX/airflow/dags/x_dag.py for tasks to queue
[2025-10-14 18:08:03,219] {logging_mixin.py:115} INFO - [2025-10-14 18:08:03,219] {dagbag.py:507} INFO - Filling up the DagBag from /root/Projects/etlX/airflow/dags/x_dag.py
[2025-10-14 18:08:03,235] {processor.py:651} INFO - DAG(s) dict_keys(['x_DAG']) retrieved from /root/Projects/etlX/airflow/dags/x_dag.py
[2025-10-14 18:08:03,289] {logging_mixin.py:115} INFO - [2025-10-14 18:08:03,289] {dag.py:2379} INFO - Sync 1 DAGs
[2025-10-14 18:08:03,305] {logging_mixin.py:115} INFO - [2025-10-14 18:08:03,305] {dag.py:2927} INFO - Setting next_dagrun for x_DAG to 2025-10-12T00:00:00+00:00, run_after=2025-10-13T00:00:00+00:00
[2025-10-14 18:08:03,320] {processor.py:161} INFO - Processing /root/Projects/etlX/airflow/dags/x_dag.py took 0.107 seconds
[2025-10-14 18:08:33,444] {processor.py:153} INFO - Started process (PID=31079) to work on /root/Projects/etlX/airflow/dags/x_dag.py
[2025-10-14 18:08:33,445] {processor.py:641} INFO - Processing file /root/Projects/etlX/airflow/dags/x_dag.py for tasks to queue
[2025-10-14 18:08:33,446] {logging_mixin.py:115} INFO - [2025-10-14 18:08:33,446] {dagbag.py:507} INFO - Filling up the DagBag from /root/Projects/etlX/airflow/dags/x_dag.py
[2025-10-14 18:08:33,459] {processor.py:651} INFO - DAG(s) dict_keys(['x_DAG']) retrieved from /root/Projects/etlX/airflow/dags/x_dag.py
[2025-10-14 18:08:33,511] {logging_mixin.py:115} INFO - [2025-10-14 18:08:33,511] {dag.py:2379} INFO - Sync 1 DAGs
[2025-10-14 18:08:33,527] {logging_mixin.py:115} INFO - [2025-10-14 18:08:33,527] {dag.py:2927} INFO - Setting next_dagrun for x_DAG to 2025-10-12T00:00:00+00:00, run_after=2025-10-13T00:00:00+00:00
[2025-10-14 18:08:33,541] {processor.py:161} INFO - Processing /root/Projects/etlX/airflow/dags/x_dag.py took 0.101 seconds
[2025-10-14 18:09:03,705] {processor.py:153} INFO - Started process (PID=31101) to work on /root/Projects/etlX/airflow/dags/x_dag.py
[2025-10-14 18:09:03,705] {processor.py:641} INFO - Processing file /root/Projects/etlX/airflow/dags/x_dag.py for tasks to queue
[2025-10-14 18:09:03,707] {logging_mixin.py:115} INFO - [2025-10-14 18:09:03,706] {dagbag.py:507} INFO - Filling up the DagBag from /root/Projects/etlX/airflow/dags/x_dag.py
[2025-10-14 18:09:03,720] {processor.py:651} INFO - DAG(s) dict_keys(['x_DAG']) retrieved from /root/Projects/etlX/airflow/dags/x_dag.py
[2025-10-14 18:09:03,772] {logging_mixin.py:115} INFO - [2025-10-14 18:09:03,772] {dag.py:2379} INFO - Sync 1 DAGs
[2025-10-14 18:09:03,787] {logging_mixin.py:115} INFO - [2025-10-14 18:09:03,787] {dag.py:2927} INFO - Setting next_dagrun for x_DAG to 2025-10-12T00:00:00+00:00, run_after=2025-10-13T00:00:00+00:00
[2025-10-14 18:09:03,800] {processor.py:161} INFO - Processing /root/Projects/etlX/airflow/dags/x_dag.py took 0.100 seconds
[2025-10-14 18:09:33,976] {processor.py:153} INFO - Started process (PID=31120) to work on /root/Projects/etlX/airflow/dags/x_dag.py
[2025-10-14 18:09:33,977] {processor.py:641} INFO - Processing file /root/Projects/etlX/airflow/dags/x_dag.py for tasks to queue
[2025-10-14 18:09:33,977] {logging_mixin.py:115} INFO - [2025-10-14 18:09:33,977] {dagbag.py:507} INFO - Filling up the DagBag from /root/Projects/etlX/airflow/dags/x_dag.py
[2025-10-14 18:09:33,982] {logging_mixin.py:115} INFO - [2025-10-14 18:09:33,981] {dagbag.py:320} ERROR - Failed to import: /root/Projects/etlX/airflow/dags/x_dag.py
Traceback (most recent call last):
  File "/root/Projects/etlX/venv/lib/python3.9/site-packages/airflow/models/dagbag.py", line 317, in parse
    loader.exec_module(new_module)
  File "<frozen importlib._bootstrap_external>", line 851, in exec_module
  File "<frozen importlib._bootstrap_external>", line 988, in get_code
  File "<frozen importlib._bootstrap_external>", line 918, in source_to_code
  File "<frozen importlib._bootstrap>", line 228, in _call_with_frames_removed
  File "/root/Projects/etlX/airflow/dags/x_dag.py", line 18
    query=query, start_time{{ data_interval }}, end_time=end_time, task_id='x_datascience')
                           ^
SyntaxError: invalid syntax
[2025-10-14 18:09:33,982] {processor.py:653} WARNING - No viable dags retrieved from /root/Projects/etlX/airflow/dags/x_dag.py
[2025-10-14 18:09:34,008] {processor.py:161} INFO - Processing /root/Projects/etlX/airflow/dags/x_dag.py took 0.036 seconds
[2025-10-14 18:10:04,233] {processor.py:153} INFO - Started process (PID=31142) to work on /root/Projects/etlX/airflow/dags/x_dag.py
[2025-10-14 18:10:04,234] {processor.py:641} INFO - Processing file /root/Projects/etlX/airflow/dags/x_dag.py for tasks to queue
[2025-10-14 18:10:04,235] {logging_mixin.py:115} INFO - [2025-10-14 18:10:04,235] {dagbag.py:507} INFO - Filling up the DagBag from /root/Projects/etlX/airflow/dags/x_dag.py
[2025-10-14 18:10:04,240] {logging_mixin.py:115} INFO - [2025-10-14 18:10:04,239] {dagbag.py:320} ERROR - Failed to import: /root/Projects/etlX/airflow/dags/x_dag.py
Traceback (most recent call last):
  File "/root/Projects/etlX/venv/lib/python3.9/site-packages/airflow/models/dagbag.py", line 317, in parse
    loader.exec_module(new_module)
  File "<frozen importlib._bootstrap_external>", line 851, in exec_module
  File "<frozen importlib._bootstrap_external>", line 988, in get_code
  File "<frozen importlib._bootstrap_external>", line 918, in source_to_code
  File "<frozen importlib._bootstrap>", line 228, in _call_with_frames_removed
  File "/root/Projects/etlX/airflow/dags/x_dag.py", line 18
    query=query, start_time{{ data_interval }}, end_time=end_time, task_id='x_datascience')
                           ^
SyntaxError: invalid syntax
[2025-10-14 18:10:04,241] {processor.py:653} WARNING - No viable dags retrieved from /root/Projects/etlX/airflow/dags/x_dag.py
[2025-10-14 18:10:04,269] {processor.py:161} INFO - Processing /root/Projects/etlX/airflow/dags/x_dag.py took 0.043 seconds
[2025-10-14 18:10:34,469] {processor.py:153} INFO - Started process (PID=31161) to work on /root/Projects/etlX/airflow/dags/x_dag.py
[2025-10-14 18:10:34,469] {processor.py:641} INFO - Processing file /root/Projects/etlX/airflow/dags/x_dag.py for tasks to queue
[2025-10-14 18:10:34,470] {logging_mixin.py:115} INFO - [2025-10-14 18:10:34,470] {dagbag.py:507} INFO - Filling up the DagBag from /root/Projects/etlX/airflow/dags/x_dag.py
[2025-10-14 18:10:34,474] {logging_mixin.py:115} INFO - [2025-10-14 18:10:34,474] {dagbag.py:320} ERROR - Failed to import: /root/Projects/etlX/airflow/dags/x_dag.py
Traceback (most recent call last):
  File "/root/Projects/etlX/venv/lib/python3.9/site-packages/airflow/models/dagbag.py", line 317, in parse
    loader.exec_module(new_module)
  File "<frozen importlib._bootstrap_external>", line 851, in exec_module
  File "<frozen importlib._bootstrap_external>", line 988, in get_code
  File "<frozen importlib._bootstrap_external>", line 918, in source_to_code
  File "<frozen importlib._bootstrap>", line 228, in _call_with_frames_removed
  File "/root/Projects/etlX/airflow/dags/x_dag.py", line 18
    query=query, start_time{{ data_interval }}, end_time=end_time, task_id='x_datascience')
                           ^
SyntaxError: invalid syntax
[2025-10-14 18:10:34,475] {processor.py:653} WARNING - No viable dags retrieved from /root/Projects/etlX/airflow/dags/x_dag.py
[2025-10-14 18:10:34,497] {processor.py:161} INFO - Processing /root/Projects/etlX/airflow/dags/x_dag.py took 0.033 seconds
[2025-10-14 18:11:04,751] {processor.py:153} INFO - Started process (PID=31336) to work on /root/Projects/etlX/airflow/dags/x_dag.py
[2025-10-14 18:11:04,752] {processor.py:641} INFO - Processing file /root/Projects/etlX/airflow/dags/x_dag.py for tasks to queue
[2025-10-14 18:11:04,753] {logging_mixin.py:115} INFO - [2025-10-14 18:11:04,753] {dagbag.py:507} INFO - Filling up the DagBag from /root/Projects/etlX/airflow/dags/x_dag.py
[2025-10-14 18:11:04,774] {processor.py:651} INFO - DAG(s) dict_keys(['x_DAG']) retrieved from /root/Projects/etlX/airflow/dags/x_dag.py
[2025-10-14 18:11:04,851] {logging_mixin.py:115} INFO - [2025-10-14 18:11:04,851] {dag.py:2379} INFO - Sync 1 DAGs
[2025-10-14 18:11:04,874] {logging_mixin.py:115} INFO - [2025-10-14 18:11:04,874] {dag.py:2927} INFO - Setting next_dagrun for x_DAG to 2025-10-12T00:00:00+00:00, run_after=2025-10-13T00:00:00+00:00
[2025-10-14 18:11:04,894] {processor.py:161} INFO - Processing /root/Projects/etlX/airflow/dags/x_dag.py took 0.148 seconds
[2025-10-14 18:11:35,025] {processor.py:153} INFO - Started process (PID=31355) to work on /root/Projects/etlX/airflow/dags/x_dag.py
[2025-10-14 18:11:35,026] {processor.py:641} INFO - Processing file /root/Projects/etlX/airflow/dags/x_dag.py for tasks to queue
[2025-10-14 18:11:35,027] {logging_mixin.py:115} INFO - [2025-10-14 18:11:35,027] {dagbag.py:507} INFO - Filling up the DagBag from /root/Projects/etlX/airflow/dags/x_dag.py
[2025-10-14 18:11:35,046] {processor.py:651} INFO - DAG(s) dict_keys(['x_DAG']) retrieved from /root/Projects/etlX/airflow/dags/x_dag.py
[2025-10-14 18:11:35,077] {logging_mixin.py:115} INFO - [2025-10-14 18:11:35,077] {dag.py:2379} INFO - Sync 1 DAGs
[2025-10-14 18:11:35,113] {logging_mixin.py:115} INFO - [2025-10-14 18:11:35,112] {dag.py:2927} INFO - Setting next_dagrun for x_DAG to 2025-10-12T00:00:00+00:00, run_after=2025-10-13T00:00:00+00:00
[2025-10-14 18:11:35,131] {processor.py:161} INFO - Processing /root/Projects/etlX/airflow/dags/x_dag.py took 0.112 seconds
[2025-10-14 18:12:05,249] {processor.py:153} INFO - Started process (PID=31374) to work on /root/Projects/etlX/airflow/dags/x_dag.py
[2025-10-14 18:12:05,250] {processor.py:641} INFO - Processing file /root/Projects/etlX/airflow/dags/x_dag.py for tasks to queue
[2025-10-14 18:12:05,250] {logging_mixin.py:115} INFO - [2025-10-14 18:12:05,250] {dagbag.py:507} INFO - Filling up the DagBag from /root/Projects/etlX/airflow/dags/x_dag.py
[2025-10-14 18:12:05,265] {processor.py:651} INFO - DAG(s) dict_keys(['x_DAG']) retrieved from /root/Projects/etlX/airflow/dags/x_dag.py
[2025-10-14 18:12:05,318] {logging_mixin.py:115} INFO - [2025-10-14 18:12:05,318] {dag.py:2379} INFO - Sync 1 DAGs
[2025-10-14 18:12:05,336] {logging_mixin.py:115} INFO - [2025-10-14 18:12:05,336] {dag.py:2927} INFO - Setting next_dagrun for x_DAG to 2025-10-12T00:00:00+00:00, run_after=2025-10-13T00:00:00+00:00
[2025-10-14 18:12:05,350] {processor.py:161} INFO - Processing /root/Projects/etlX/airflow/dags/x_dag.py took 0.106 seconds
[2025-10-14 18:12:35,479] {processor.py:153} INFO - Started process (PID=31396) to work on /root/Projects/etlX/airflow/dags/x_dag.py
[2025-10-14 18:12:35,480] {processor.py:641} INFO - Processing file /root/Projects/etlX/airflow/dags/x_dag.py for tasks to queue
[2025-10-14 18:12:35,480] {logging_mixin.py:115} INFO - [2025-10-14 18:12:35,480] {dagbag.py:507} INFO - Filling up the DagBag from /root/Projects/etlX/airflow/dags/x_dag.py
[2025-10-14 18:12:35,493] {processor.py:651} INFO - DAG(s) dict_keys(['x_DAG']) retrieved from /root/Projects/etlX/airflow/dags/x_dag.py
[2025-10-14 18:12:35,514] {logging_mixin.py:115} INFO - [2025-10-14 18:12:35,513] {dag.py:2379} INFO - Sync 1 DAGs
[2025-10-14 18:12:35,537] {logging_mixin.py:115} INFO - [2025-10-14 18:12:35,537] {dag.py:2927} INFO - Setting next_dagrun for x_DAG to 2025-10-12T00:00:00+00:00, run_after=2025-10-13T00:00:00+00:00
[2025-10-14 18:12:35,549] {processor.py:161} INFO - Processing /root/Projects/etlX/airflow/dags/x_dag.py took 0.075 seconds
[2025-10-14 18:13:05,689] {processor.py:153} INFO - Started process (PID=31415) to work on /root/Projects/etlX/airflow/dags/x_dag.py
[2025-10-14 18:13:05,690] {processor.py:641} INFO - Processing file /root/Projects/etlX/airflow/dags/x_dag.py for tasks to queue
[2025-10-14 18:13:05,691] {logging_mixin.py:115} INFO - [2025-10-14 18:13:05,690] {dagbag.py:507} INFO - Filling up the DagBag from /root/Projects/etlX/airflow/dags/x_dag.py
[2025-10-14 18:13:05,716] {processor.py:651} INFO - DAG(s) dict_keys(['x_DAG']) retrieved from /root/Projects/etlX/airflow/dags/x_dag.py
[2025-10-14 18:13:05,781] {logging_mixin.py:115} INFO - [2025-10-14 18:13:05,781] {dag.py:2379} INFO - Sync 1 DAGs
[2025-10-14 18:13:05,808] {logging_mixin.py:115} INFO - [2025-10-14 18:13:05,808] {dag.py:2927} INFO - Setting next_dagrun for x_DAG to 2025-10-12T00:00:00+00:00, run_after=2025-10-13T00:00:00+00:00
[2025-10-14 18:13:05,826] {processor.py:161} INFO - Processing /root/Projects/etlX/airflow/dags/x_dag.py took 0.142 seconds
[2025-10-14 18:13:35,962] {processor.py:153} INFO - Started process (PID=31539) to work on /root/Projects/etlX/airflow/dags/x_dag.py
[2025-10-14 18:13:35,962] {processor.py:641} INFO - Processing file /root/Projects/etlX/airflow/dags/x_dag.py for tasks to queue
[2025-10-14 18:13:35,963] {logging_mixin.py:115} INFO - [2025-10-14 18:13:35,963] {dagbag.py:507} INFO - Filling up the DagBag from /root/Projects/etlX/airflow/dags/x_dag.py
[2025-10-14 18:13:35,979] {processor.py:651} INFO - DAG(s) dict_keys(['x_DAG']) retrieved from /root/Projects/etlX/airflow/dags/x_dag.py
[2025-10-14 18:13:36,009] {logging_mixin.py:115} INFO - [2025-10-14 18:13:36,009] {dag.py:2379} INFO - Sync 1 DAGs
[2025-10-14 18:13:36,039] {logging_mixin.py:115} INFO - [2025-10-14 18:13:36,039] {dag.py:2927} INFO - Setting next_dagrun for x_DAG to 2025-10-12T00:00:00+00:00, run_after=2025-10-13T00:00:00+00:00
[2025-10-14 18:13:36,053] {processor.py:161} INFO - Processing /root/Projects/etlX/airflow/dags/x_dag.py took 0.097 seconds
[2025-10-14 18:14:12,281] {processor.py:153} INFO - Started process (PID=31777) to work on /root/Projects/etlX/airflow/dags/x_dag.py
[2025-10-14 18:14:12,282] {processor.py:641} INFO - Processing file /root/Projects/etlX/airflow/dags/x_dag.py for tasks to queue
[2025-10-14 18:14:12,282] {logging_mixin.py:115} INFO - [2025-10-14 18:14:12,282] {dagbag.py:507} INFO - Filling up the DagBag from /root/Projects/etlX/airflow/dags/x_dag.py
[2025-10-14 18:14:12,300] {processor.py:651} INFO - DAG(s) dict_keys(['x_DAG']) retrieved from /root/Projects/etlX/airflow/dags/x_dag.py
[2025-10-14 18:14:12,371] {logging_mixin.py:115} INFO - [2025-10-14 18:14:12,371] {dag.py:2379} INFO - Sync 1 DAGs
[2025-10-14 18:14:12,379] {logging_mixin.py:115} INFO - [2025-10-14 18:14:12,379] {dag.py:2398} INFO - Creating ORM DAG for x_DAG
[2025-10-14 18:14:12,392] {logging_mixin.py:115} INFO - [2025-10-14 18:14:12,392] {dag.py:2927} INFO - Setting next_dagrun for x_DAG to 2025-10-12T00:00:00+00:00, run_after=2025-10-13T00:00:00+00:00
[2025-10-14 18:14:12,410] {processor.py:161} INFO - Processing /root/Projects/etlX/airflow/dags/x_dag.py took 0.137 seconds
[2025-10-14 18:14:43,500] {processor.py:153} INFO - Started process (PID=32019) to work on /root/Projects/etlX/airflow/dags/x_dag.py
[2025-10-14 18:14:43,500] {processor.py:641} INFO - Processing file /root/Projects/etlX/airflow/dags/x_dag.py for tasks to queue
[2025-10-14 18:14:43,501] {logging_mixin.py:115} INFO - [2025-10-14 18:14:43,501] {dagbag.py:507} INFO - Filling up the DagBag from /root/Projects/etlX/airflow/dags/x_dag.py
[2025-10-14 18:14:43,516] {processor.py:651} INFO - DAG(s) dict_keys(['x_DAG']) retrieved from /root/Projects/etlX/airflow/dags/x_dag.py
[2025-10-14 18:14:43,537] {logging_mixin.py:115} INFO - [2025-10-14 18:14:43,537] {dag.py:2379} INFO - Sync 1 DAGs
[2025-10-14 18:14:43,559] {logging_mixin.py:115} INFO - [2025-10-14 18:14:43,559] {dag.py:2927} INFO - Setting next_dagrun for x_DAG to 2025-10-12T00:00:00+00:00, run_after=2025-10-13T00:00:00+00:00
[2025-10-14 18:14:43,572] {processor.py:161} INFO - Processing /root/Projects/etlX/airflow/dags/x_dag.py took 0.078 seconds
[2025-10-14 18:15:13,964] {processor.py:153} INFO - Started process (PID=32140) to work on /root/Projects/etlX/airflow/dags/x_dag.py
[2025-10-14 18:15:13,965] {processor.py:641} INFO - Processing file /root/Projects/etlX/airflow/dags/x_dag.py for tasks to queue
[2025-10-14 18:15:13,965] {logging_mixin.py:115} INFO - [2025-10-14 18:15:13,965] {dagbag.py:507} INFO - Filling up the DagBag from /root/Projects/etlX/airflow/dags/x_dag.py
[2025-10-14 18:15:13,979] {processor.py:651} INFO - DAG(s) dict_keys(['x_DAG']) retrieved from /root/Projects/etlX/airflow/dags/x_dag.py
[2025-10-14 18:15:14,001] {logging_mixin.py:115} INFO - [2025-10-14 18:15:14,001] {dag.py:2379} INFO - Sync 1 DAGs
[2025-10-14 18:15:14,028] {logging_mixin.py:115} INFO - [2025-10-14 18:15:14,028] {dag.py:2927} INFO - Setting next_dagrun for x_DAG to 2025-10-12T00:00:00+00:00, run_after=2025-10-13T00:00:00+00:00
[2025-10-14 18:15:14,040] {processor.py:161} INFO - Processing /root/Projects/etlX/airflow/dags/x_dag.py took 0.081 seconds
[2025-10-14 18:15:44,257] {processor.py:153} INFO - Started process (PID=32184) to work on /root/Projects/etlX/airflow/dags/x_dag.py
[2025-10-14 18:15:44,259] {processor.py:641} INFO - Processing file /root/Projects/etlX/airflow/dags/x_dag.py for tasks to queue
[2025-10-14 18:15:44,259] {logging_mixin.py:115} INFO - [2025-10-14 18:15:44,259] {dagbag.py:507} INFO - Filling up the DagBag from /root/Projects/etlX/airflow/dags/x_dag.py
[2025-10-14 18:15:44,279] {processor.py:651} INFO - DAG(s) dict_keys(['x_DAG']) retrieved from /root/Projects/etlX/airflow/dags/x_dag.py
[2025-10-14 18:15:44,308] {logging_mixin.py:115} INFO - [2025-10-14 18:15:44,308] {dag.py:2379} INFO - Sync 1 DAGs
[2025-10-14 18:15:44,364] {logging_mixin.py:115} INFO - [2025-10-14 18:15:44,364] {dag.py:2927} INFO - Setting next_dagrun for x_DAG to 2025-10-12T00:00:00+00:00, run_after=2025-10-13T00:00:00+00:00
[2025-10-14 18:15:44,384] {processor.py:161} INFO - Processing /root/Projects/etlX/airflow/dags/x_dag.py took 0.133 seconds
[2025-10-14 18:16:14,531] {processor.py:153} INFO - Started process (PID=32232) to work on /root/Projects/etlX/airflow/dags/x_dag.py
[2025-10-14 18:16:14,532] {processor.py:641} INFO - Processing file /root/Projects/etlX/airflow/dags/x_dag.py for tasks to queue
[2025-10-14 18:16:14,533] {logging_mixin.py:115} INFO - [2025-10-14 18:16:14,533] {dagbag.py:507} INFO - Filling up the DagBag from /root/Projects/etlX/airflow/dags/x_dag.py
[2025-10-14 18:16:14,547] {processor.py:651} INFO - DAG(s) dict_keys(['x_DAG']) retrieved from /root/Projects/etlX/airflow/dags/x_dag.py
[2025-10-14 18:16:14,568] {logging_mixin.py:115} INFO - [2025-10-14 18:16:14,568] {dag.py:2379} INFO - Sync 1 DAGs
[2025-10-14 18:16:14,590] {logging_mixin.py:115} INFO - [2025-10-14 18:16:14,590] {dag.py:2927} INFO - Setting next_dagrun for x_DAG to 2025-10-12T00:00:00+00:00, run_after=2025-10-13T00:00:00+00:00
[2025-10-14 18:16:14,609] {processor.py:161} INFO - Processing /root/Projects/etlX/airflow/dags/x_dag.py took 0.082 seconds
[2025-10-14 18:16:44,790] {processor.py:153} INFO - Started process (PID=32353) to work on /root/Projects/etlX/airflow/dags/x_dag.py
[2025-10-14 18:16:44,791] {processor.py:641} INFO - Processing file /root/Projects/etlX/airflow/dags/x_dag.py for tasks to queue
[2025-10-14 18:16:44,792] {logging_mixin.py:115} INFO - [2025-10-14 18:16:44,791] {dagbag.py:507} INFO - Filling up the DagBag from /root/Projects/etlX/airflow/dags/x_dag.py
[2025-10-14 18:16:44,814] {processor.py:651} INFO - DAG(s) dict_keys(['x_DAG']) retrieved from /root/Projects/etlX/airflow/dags/x_dag.py
[2025-10-14 18:16:44,837] {logging_mixin.py:115} INFO - [2025-10-14 18:16:44,837] {dag.py:2379} INFO - Sync 1 DAGs
[2025-10-14 18:16:44,868] {logging_mixin.py:115} INFO - [2025-10-14 18:16:44,868] {dag.py:2927} INFO - Setting next_dagrun for x_DAG to 2025-10-12T00:00:00+00:00, run_after=2025-10-13T00:00:00+00:00
[2025-10-14 18:16:44,887] {processor.py:161} INFO - Processing /root/Projects/etlX/airflow/dags/x_dag.py took 0.105 seconds
[2025-10-14 18:17:16,027] {processor.py:153} INFO - Started process (PID=32375) to work on /root/Projects/etlX/airflow/dags/x_dag.py
[2025-10-14 18:17:16,028] {processor.py:641} INFO - Processing file /root/Projects/etlX/airflow/dags/x_dag.py for tasks to queue
[2025-10-14 18:17:16,029] {logging_mixin.py:115} INFO - [2025-10-14 18:17:16,029] {dagbag.py:507} INFO - Filling up the DagBag from /root/Projects/etlX/airflow/dags/x_dag.py
[2025-10-14 18:17:16,052] {processor.py:651} INFO - DAG(s) dict_keys(['x_DAG']) retrieved from /root/Projects/etlX/airflow/dags/x_dag.py
[2025-10-14 18:17:16,077] {logging_mixin.py:115} INFO - [2025-10-14 18:17:16,077] {dag.py:2379} INFO - Sync 1 DAGs
[2025-10-14 18:17:16,107] {logging_mixin.py:115} INFO - [2025-10-14 18:17:16,107] {dag.py:2927} INFO - Setting next_dagrun for x_DAG to 2025-10-12T00:00:00+00:00, run_after=2025-10-13T00:00:00+00:00
[2025-10-14 18:17:16,121] {processor.py:161} INFO - Processing /root/Projects/etlX/airflow/dags/x_dag.py took 0.099 seconds
[2025-10-14 18:17:46,275] {processor.py:153} INFO - Started process (PID=32394) to work on /root/Projects/etlX/airflow/dags/x_dag.py
[2025-10-14 18:17:46,276] {processor.py:641} INFO - Processing file /root/Projects/etlX/airflow/dags/x_dag.py for tasks to queue
[2025-10-14 18:17:46,276] {logging_mixin.py:115} INFO - [2025-10-14 18:17:46,276] {dagbag.py:507} INFO - Filling up the DagBag from /root/Projects/etlX/airflow/dags/x_dag.py
[2025-10-14 18:17:46,289] {processor.py:651} INFO - DAG(s) dict_keys(['x_DAG']) retrieved from /root/Projects/etlX/airflow/dags/x_dag.py
[2025-10-14 18:17:46,309] {logging_mixin.py:115} INFO - [2025-10-14 18:17:46,309] {dag.py:2379} INFO - Sync 1 DAGs
[2025-10-14 18:17:46,334] {logging_mixin.py:115} INFO - [2025-10-14 18:17:46,334] {dag.py:2927} INFO - Setting next_dagrun for x_DAG to 2025-10-12T00:00:00+00:00, run_after=2025-10-13T00:00:00+00:00
[2025-10-14 18:17:46,352] {processor.py:161} INFO - Processing /root/Projects/etlX/airflow/dags/x_dag.py took 0.081 seconds
[2025-10-14 18:18:16,949] {processor.py:153} INFO - Started process (PID=32576) to work on /root/Projects/etlX/airflow/dags/x_dag.py
[2025-10-14 18:18:16,950] {processor.py:641} INFO - Processing file /root/Projects/etlX/airflow/dags/x_dag.py for tasks to queue
[2025-10-14 18:18:16,950] {logging_mixin.py:115} INFO - [2025-10-14 18:18:16,950] {dagbag.py:507} INFO - Filling up the DagBag from /root/Projects/etlX/airflow/dags/x_dag.py
[2025-10-14 18:18:16,964] {processor.py:651} INFO - DAG(s) dict_keys(['x_DAG']) retrieved from /root/Projects/etlX/airflow/dags/x_dag.py
[2025-10-14 18:18:16,984] {logging_mixin.py:115} INFO - [2025-10-14 18:18:16,984] {dag.py:2379} INFO - Sync 1 DAGs
[2025-10-14 18:18:17,006] {logging_mixin.py:115} INFO - [2025-10-14 18:18:17,006] {dag.py:2927} INFO - Setting next_dagrun for x_DAG to 2025-10-14T00:00:00+00:00, run_after=2025-10-15T00:00:00+00:00
[2025-10-14 18:18:17,017] {processor.py:161} INFO - Processing /root/Projects/etlX/airflow/dags/x_dag.py took 0.072 seconds
[2025-10-14 18:18:47,222] {processor.py:153} INFO - Started process (PID=88) to work on /root/Projects/etlX/airflow/dags/x_dag.py
[2025-10-14 18:18:47,222] {processor.py:641} INFO - Processing file /root/Projects/etlX/airflow/dags/x_dag.py for tasks to queue
[2025-10-14 18:18:47,223] {logging_mixin.py:115} INFO - [2025-10-14 18:18:47,223] {dagbag.py:507} INFO - Filling up the DagBag from /root/Projects/etlX/airflow/dags/x_dag.py
[2025-10-14 18:18:47,237] {processor.py:651} INFO - DAG(s) dict_keys(['x_DAG']) retrieved from /root/Projects/etlX/airflow/dags/x_dag.py
[2025-10-14 18:18:47,258] {logging_mixin.py:115} INFO - [2025-10-14 18:18:47,258] {dag.py:2379} INFO - Sync 1 DAGs
[2025-10-14 18:18:47,280] {logging_mixin.py:115} INFO - [2025-10-14 18:18:47,280] {dag.py:2927} INFO - Setting next_dagrun for x_DAG to 2025-10-14T00:00:00+00:00, run_after=2025-10-15T00:00:00+00:00
[2025-10-14 18:18:47,291] {processor.py:161} INFO - Processing /root/Projects/etlX/airflow/dags/x_dag.py took 0.074 seconds
[2025-10-14 18:19:17,447] {processor.py:153} INFO - Started process (PID=380) to work on /root/Projects/etlX/airflow/dags/x_dag.py
[2025-10-14 18:19:17,448] {processor.py:641} INFO - Processing file /root/Projects/etlX/airflow/dags/x_dag.py for tasks to queue
[2025-10-14 18:19:17,449] {logging_mixin.py:115} INFO - [2025-10-14 18:19:17,449] {dagbag.py:507} INFO - Filling up the DagBag from /root/Projects/etlX/airflow/dags/x_dag.py
[2025-10-14 18:19:17,464] {processor.py:651} INFO - DAG(s) dict_keys(['x_DAG']) retrieved from /root/Projects/etlX/airflow/dags/x_dag.py
[2025-10-14 18:19:17,486] {logging_mixin.py:115} INFO - [2025-10-14 18:19:17,486] {dag.py:2379} INFO - Sync 1 DAGs
[2025-10-14 18:19:17,508] {logging_mixin.py:115} INFO - [2025-10-14 18:19:17,508] {dag.py:2927} INFO - Setting next_dagrun for x_DAG to 2025-10-14T00:00:00+00:00, run_after=2025-10-15T00:00:00+00:00
[2025-10-14 18:19:17,520] {processor.py:161} INFO - Processing /root/Projects/etlX/airflow/dags/x_dag.py took 0.078 seconds
[2025-10-14 18:19:47,712] {processor.py:153} INFO - Started process (PID=510) to work on /root/Projects/etlX/airflow/dags/x_dag.py
[2025-10-14 18:19:47,713] {processor.py:641} INFO - Processing file /root/Projects/etlX/airflow/dags/x_dag.py for tasks to queue
[2025-10-14 18:19:47,714] {logging_mixin.py:115} INFO - [2025-10-14 18:19:47,713] {dagbag.py:507} INFO - Filling up the DagBag from /root/Projects/etlX/airflow/dags/x_dag.py
[2025-10-14 18:19:47,731] {processor.py:651} INFO - DAG(s) dict_keys(['x_DAG']) retrieved from /root/Projects/etlX/airflow/dags/x_dag.py
[2025-10-14 18:19:47,753] {logging_mixin.py:115} INFO - [2025-10-14 18:19:47,753] {dag.py:2379} INFO - Sync 1 DAGs
[2025-10-14 18:19:47,777] {logging_mixin.py:115} INFO - [2025-10-14 18:19:47,777] {dag.py:2927} INFO - Setting next_dagrun for x_DAG to 2025-10-14T00:00:00+00:00, run_after=2025-10-15T00:00:00+00:00
[2025-10-14 18:19:47,789] {processor.py:161} INFO - Processing /root/Projects/etlX/airflow/dags/x_dag.py took 0.082 seconds
[2025-10-14 18:20:18,029] {processor.py:153} INFO - Started process (PID=755) to work on /root/Projects/etlX/airflow/dags/x_dag.py
[2025-10-14 18:20:18,030] {processor.py:641} INFO - Processing file /root/Projects/etlX/airflow/dags/x_dag.py for tasks to queue
[2025-10-14 18:20:18,030] {logging_mixin.py:115} INFO - [2025-10-14 18:20:18,030] {dagbag.py:507} INFO - Filling up the DagBag from /root/Projects/etlX/airflow/dags/x_dag.py
[2025-10-14 18:20:18,049] {processor.py:651} INFO - DAG(s) dict_keys(['x_DAG']) retrieved from /root/Projects/etlX/airflow/dags/x_dag.py
[2025-10-14 18:20:18,072] {logging_mixin.py:115} INFO - [2025-10-14 18:20:18,072] {dag.py:2379} INFO - Sync 1 DAGs
[2025-10-14 18:20:18,108] {logging_mixin.py:115} INFO - [2025-10-14 18:20:18,108] {dag.py:2927} INFO - Setting next_dagrun for x_DAG to 2025-10-14T00:00:00+00:00, run_after=2025-10-15T00:00:00+00:00
[2025-10-14 18:20:18,124] {processor.py:161} INFO - Processing /root/Projects/etlX/airflow/dags/x_dag.py took 0.101 seconds
[2025-10-14 18:20:48,251] {processor.py:153} INFO - Started process (PID=908) to work on /root/Projects/etlX/airflow/dags/x_dag.py
[2025-10-14 18:20:48,252] {processor.py:641} INFO - Processing file /root/Projects/etlX/airflow/dags/x_dag.py for tasks to queue
[2025-10-14 18:20:48,253] {logging_mixin.py:115} INFO - [2025-10-14 18:20:48,253] {dagbag.py:507} INFO - Filling up the DagBag from /root/Projects/etlX/airflow/dags/x_dag.py
[2025-10-14 18:20:48,268] {processor.py:651} INFO - DAG(s) dict_keys(['x_DAG']) retrieved from /root/Projects/etlX/airflow/dags/x_dag.py
[2025-10-14 18:20:48,291] {logging_mixin.py:115} INFO - [2025-10-14 18:20:48,291] {dag.py:2379} INFO - Sync 1 DAGs
[2025-10-14 18:20:48,316] {logging_mixin.py:115} INFO - [2025-10-14 18:20:48,316] {dag.py:2927} INFO - Setting next_dagrun for x_DAG to 2025-10-14T00:00:00+00:00, run_after=2025-10-15T00:00:00+00:00
[2025-10-14 18:20:48,330] {processor.py:161} INFO - Processing /root/Projects/etlX/airflow/dags/x_dag.py took 0.085 seconds
[2025-10-14 18:21:18,500] {processor.py:153} INFO - Started process (PID=927) to work on /root/Projects/etlX/airflow/dags/x_dag.py
[2025-10-14 18:21:18,500] {processor.py:641} INFO - Processing file /root/Projects/etlX/airflow/dags/x_dag.py for tasks to queue
[2025-10-14 18:21:18,501] {logging_mixin.py:115} INFO - [2025-10-14 18:21:18,501] {dagbag.py:507} INFO - Filling up the DagBag from /root/Projects/etlX/airflow/dags/x_dag.py
[2025-10-14 18:21:18,516] {processor.py:651} INFO - DAG(s) dict_keys(['x_DAG']) retrieved from /root/Projects/etlX/airflow/dags/x_dag.py
[2025-10-14 18:21:18,535] {logging_mixin.py:115} INFO - [2025-10-14 18:21:18,535] {dag.py:2379} INFO - Sync 1 DAGs
[2025-10-14 18:21:18,558] {logging_mixin.py:115} INFO - [2025-10-14 18:21:18,558] {dag.py:2927} INFO - Setting next_dagrun for x_DAG to 2025-10-14T00:00:00+00:00, run_after=2025-10-15T00:00:00+00:00
[2025-10-14 18:21:18,568] {processor.py:161} INFO - Processing /root/Projects/etlX/airflow/dags/x_dag.py took 0.073 seconds
[2025-10-14 18:21:48,710] {processor.py:153} INFO - Started process (PID=949) to work on /root/Projects/etlX/airflow/dags/x_dag.py
[2025-10-14 18:21:48,711] {processor.py:641} INFO - Processing file /root/Projects/etlX/airflow/dags/x_dag.py for tasks to queue
[2025-10-14 18:21:48,712] {logging_mixin.py:115} INFO - [2025-10-14 18:21:48,712] {dagbag.py:507} INFO - Filling up the DagBag from /root/Projects/etlX/airflow/dags/x_dag.py
[2025-10-14 18:21:48,728] {processor.py:651} INFO - DAG(s) dict_keys(['x_DAG']) retrieved from /root/Projects/etlX/airflow/dags/x_dag.py
[2025-10-14 18:21:48,751] {logging_mixin.py:115} INFO - [2025-10-14 18:21:48,751] {dag.py:2379} INFO - Sync 1 DAGs
[2025-10-14 18:21:48,775] {logging_mixin.py:115} INFO - [2025-10-14 18:21:48,775] {dag.py:2927} INFO - Setting next_dagrun for x_DAG to 2025-10-14T00:00:00+00:00, run_after=2025-10-15T00:00:00+00:00
[2025-10-14 18:21:48,789] {processor.py:161} INFO - Processing /root/Projects/etlX/airflow/dags/x_dag.py took 0.084 seconds
